Workbook
Name Account1: _xlfn.ANCHORARRAY(Dashboard!$H$35)
Name Account2: _xlfn.ANCHORARRAY(Dashboard!$I$35)
Name Account3: _xlfn.ANCHORARRAY(Dashboard!$J$35)
Name Account4: _xlfn.ANCHORARRAY(Dashboard!$K$35)
Name Account5: _xlfn.ANCHORARRAY(Dashboard!$L$35)
Name CheckingBalance: _xlfn.ANCHORARRAY(Dashboard!#REF!)
Name CreditBalance: _xlfn.ANCHORARRAY(Dashboard!#REF!)
Name DataTable: _xlfn.ANCHORARRAY('Helper - Dashboard'!$A$2)
Name DataTable2: _xlfn.ANCHORARRAY(Dashboard!$B$35):_xlfn.ANCHORARRAY(Dashboard!$Q$35)
Name DateList: Forecast!$D$7:$D$25
Name Dates: _xlfn.ANCHORARRAY(Dashboard!$C$35)
Name DescList: Forecast!$C$7:$C$25
Name IncomeRow: 'Monthly budget'!$B$9
Name NetBalance: _xlfn.ANCHORARRAY(Dashboard!$G$35)
Name SavingsBalance: _xlfn.ANCHORARRAY(Dashboard!$F$35)
Name Slicer_Account1: #N/A
Name Timeline_Dates: #N/A
Name TotalRow: 'Monthly budget'!$B$91
Name Transactions: _xlfn.ANCHORARRAY(Dashboard!$B$35)

Sheet Monthly budget
B1: MONTHLY BUDGET
C2: Use this sheet to enter your income and expenses. This will give you a monthly budget for you to review: use the totals - calculated based on the frequency of each item - to confirm your net budget. Once this sheet is completed the workbook will use this information to populate the other tools. If additional rows are needed, select the row where you want to add more > right click > Insert
B6: Unit | C6: Frequency | D6: Start | E6: Description | F6: US Bank | G6: Wells Fargo | H6: ADP | I6: Marcus | J6: T.Rowe Price | K6: Platinum | L6: Visa Go | M6: CareCredit | N6: Costco | P6: =F6&"/Mo" -> US Bank/Mo | Q6: =G6&"/Mo" -> Wells Fargo/Mo | R6: =H6&"/Mo" -> ADP/Mo | S6: =I6&"/Mo" -> Marcus/Mo | T6: =J6&"/Mo" -> T.Rowe Price/Mo | U6: =K6&"/Mo" -> Platinum/Mo | V6: =L6&"/Mo" -> Visa Go/Mo | W6: =M6&"/Mo" -> CareCredit/Mo | ... Y6: =O6&"/Mo" -> /Mo | Z6: =F6&"/Yr" -> US Bank/Yr | AA6: =G6&"/Yr" -> Wells Fargo/Yr | AB6: =H6&"/Yr" -> ADP/Yr | AC6: =I6&"/Yr" -> Marcus/Yr | AD6: =J6&"/Yr" -> T.Rowe Price/Yr | AE6: =K6&"/Yr" -> Platinum/Yr | AF6: =L6&"/Yr" -> Visa Go/Yr | AG6: =M6&"/Yr" -> CareCredit/Yr | ... AI6: =O6&"/Yr" -> /Yr | AJ6: Mo Subtotals | AK6: Yr Subtotals | AL6: /Mo | AM6: /Yr
F7: Checking | G7: Checking | H7: Savings | I7: Savings | J7: Savings | K7: Credit | L7: Credit | M7: Credit | N7: Credit
B9: INCOME | F9: Start | G9: Start | H9: Start | I9: Start | J9: Start | K9: Start | L9: Start | M9: Start | N9: Start | O9: Start
E10: Starting balance | F10: 2153.6 | G10: 40.01 | H10: 60.96 | I10: -4600 | J10: -1188.27 | K10: -2010 | L10: =Forecast!K7 -> -8503.82 | M10: =Forecast!L7 -> -4271.75 | N10: =Forecast!M7 -> 0 | O10: =Forecast!N7 -> 0 | P10: {=_xlfn.VSTACK("",SUMIFS(Forecast!$E$7:$E$1009,Forecast!$C$7:$C$1009,"="&OFFSET($E$11,0,0,ROW(TotalRow)-ROW(IncomeRow)-5,1),Forecast!$D$7:$D$1009,">="&'Helper - All dates'!$A$2)/'Helper - All dates'!$A$10)} | Q10: {=_xlfn.VSTACK("",SUMIFS(Forecast!$F$7:$F$1009,Forecast!$C$7:$C$1009,"="&OFFSET($E$11,0,0,ROW(TotalRow)-ROW(IncomeRow)-5,1),Forecast!$D$7:$D$1009,">="&'Helper - All dates'!$A$2)/'Helper - All dates'!$A$10)} | R10: {=_xlfn.VSTACK("",SUMIFS(Forecast!$G$7:$G$1009,Forecast!$C$7:$C$1009,"="&OFFSET($E$11,0,0,ROW(TotalRow)-ROW(IncomeRow)-5,1),Forecast!$D$7:$D$1009,">="&'Helper - All dates'!$A$2)/'Helper - All dates'!$A$10)} | S10: {=_xlfn.VSTACK("",SUMIFS(Forecast!$H$7:$H$1009,Forecast!$C$7:$C$1009,"="&OFFSET($E$11,0,0,ROW(TotalRow)-ROW(IncomeRow)-5,1),Forecast!$D$7:$D$1009,">="&'Helper - All dates'!$A$2)/'Helper - All dates'!$A$10)} | T10: {=_xlfn.VSTACK("",SUMIFS(Forecast!$I$7:$I$1009,Forecast!$C$7:$C$1009,"="&OFFSET($E$11,0,0,ROW(TotalRow)-ROW(IncomeRow)-5,1),Forecast!$D$7:$D$1009,">="&'Helper - All dates'!$A$2)/'Helper - All dates'!$A$10)} | U10: {=_xlfn.VSTACK("",SUMIFS(Forecast!$J$7:$J$1009,Forecast!$C$7:$C$1009,"="&OFFSET($E$11,0,0,ROW(TotalRow)-ROW(IncomeRow)-5,1),Forecast!$D$7:$D$1009,">="&'Helper - All dates'!$A$2)/'Helper - All dates'!$A$10)} | V10: {=_xlfn.VSTACK("",SUMIFS(Forecast!$K$7:$K$1009,Forecast!$C$7:$C$1009,"="&OFFSET($E$11,0,0,ROW(TotalRow)-ROW(IncomeRow)-5,1),Forecast!$D$7:$D$1009,">="&'Helper - All dates'!$A$2)/'Helper - All dates'!$A$10)} | W10: {=_xlfn.VSTACK("",SUMIFS(Forecast!$L$7:$L$1009,Forecast!$C$7:$C$1009,"="&OFFSET($E$11,0,0,ROW(TotalRow)-ROW(IncomeRow)-5,1),Forecast!$D$7:$D$1009,">="&'Helper - All dates'!$A$2)/'Helper - All dates'!$A$10)} | X10: {=_xlfn.VSTACK("",SUMIFS(Forecast!$M$7:$M$1009,Forecast!$C$7:$C$1009,"="&OFFSET($E$11,0,0,ROW(TotalRow)-ROW(IncomeRow)-5,1),Forecast!$D$7:$D$1009,">="&'Helper - All dates'!$A$2)/'Helper - All dates'!$A$10)} | Y10: {=_xlfn.VSTACK("",SUMIFS(Forecast!$N$7:$N$1009,Forecast!$C$7:$C$1009,"="&OFFSET($E$11,0,0,ROW(TotalRow)-ROW(IncomeRow)-5,1),Forecast!$D$7:$D$1009,">="&'Helper - All dates'!$A$2)/'Helper - All dates'!$A$10)} | Z10: {=IF(ISNUMBER(_xlfn.ANCHORARRAY(P10)),_xlfn.ANCHORARRAY(P10)*12,"")} | AA10: {=IF(ISNUMBER(_xlfn.ANCHORARRAY(Q10)),_xlfn.ANCHORARRAY(Q10)*12,"")} | AB10: {=IF(ISNUMBER(_xlfn.ANCHORARRAY(R10)),_xlfn.ANCHORARRAY(R10)*12,"")} | AC10: {=IF(ISNUMBER(_xlfn.ANCHORARRAY(S10)),_xlfn.ANCHORARRAY(S10)*12,"")} | AD10: {=IF(ISNUMBER(_xlfn.ANCHORARRAY(T10)),_xlfn.ANCHORARRAY(T10)*12,"")} | AE10: {=IF(ISNUMBER(_xlfn.ANCHORARRAY(U10)),_xlfn.ANCHORARRAY(U10)*12,"")} | AF10: {=IF(ISNUMBER(_xlfn.ANCHORARRAY(V10)),_xlfn.ANCHORARRAY(V10)*12,"")} | AG10: {=IF(ISNUMBER(_xlfn.ANCHORARRAY(W10)),_xlfn.ANCHORARRAY(W10)*12,"")} | ... AI10: {=IF(ISNUMBER(_xlfn.ANCHORARRAY(Y10)),_xlfn.ANCHORARRAY(Y10)*12,"")} | AL10: {=_xlfn.LET(_xlpm.SumList,IFERROR(_xlfn.ANCHORARRAY($P$10)+_xlfn.ANCHORARRAY($Q$10)+_xlfn.ANCHORARRAY($R$10)+_xlfn.ANCHORARRAY($S$10)+_xlfn.ANCHORARRAY($T$10)+_xlfn.ANCHORARRAY($U$10)+_xlfn.ANCHORARRAY($V$10)+_xlfn.ANCHORARRAY($W$10)+_xlfn.ANCHORARRAY($X$10)+_xlfn.ANCHORARRAY($Y$10),""),_xlfn.LET(_xlpm.BCol,OFFSET($B$1,ROW(IncomeRow),,ROW(TotalRow)-ROW(IncomeRow)-4),IF(_xlpm.BCol<>"TOTAL",_xlpm.SumList,OFFSET(_xlpm.BCol,0,34))))} | AM10: {=_xlfn.LET(_xlpm.SumList,IFERROR(_xlfn.ANCHORARRAY($Z$10)+_xlfn.ANCHORARRAY($AA$10)+_xlfn.ANCHORARRAY($AB$10)+_xlfn.ANCHORARRAY($AC$10)+_xlfn.ANCHORARRAY($AD$10)+_xlfn.ANCHORARRAY($AE$10)+_xlfn.ANCHORARRAY($AF$10)+_xlfn.ANCHORARRAY($AG$10)+_xlfn.ANCHORARRAY($AH$10)+_xlfn.ANCHORARRAY($AI$10),""),_xlfn.LET(_xlpm.BCol,OFFSET($B$1,ROW(IncomeRow),,ROW(TotalRow)-ROW(IncomeRow)-4),IF(_xlpm.BCol<>"TOTAL",_xlpm.SumList,OFFSET(_xlpm.BCol,0,35))))}
B11: 2 | C11: week(s) | D11: 45702 | E11: Paycheck | F11: 1140 | G11: 460 | P11: 2470 | Q11: 996.66667 | R11: 0 | S11: 0 | T11: 0 | U11: 0 | V11: 0 | W11: 0 | X11: 0 | Y11: 0 | Z11: 29640 | AA11: 11960 | AB11: 0 | AC11: 0 | AD11: 0 | AE11: 0 | AF11: 0 | AG11: 0 | AH11: 0 | AI11: 0 | AL11: 3466.6667 | AM11: 41600
B12: 1 | C12: month(s) | D12: 45627 | E12: Disability | G12: 356.66 | P12: 0 | Q12: 356.66 | R12: 0 | S12: 0 | T12: 0 | U12: 0 | V12: 0 | W12: 0 | X12: 0 | Y12: 0 | Z12: 0 | AA12: 4279.92 | AB12: 0 | AC12: 0 | AD12: 0 | AE12: 0 | AF12: 0 | AG12: 0 | AH12: 0 | AI12: 0 | AL12: 356.66 | AM12: 4279.92
B13: 2 | C13: week(s) | D13: 45702 | E13: Ameritas | H13: 112 | P13: 0 | Q13: 0 | R13: 242.66667 | S13: 0 | T13: 0 | U13: 0 | V13: 0 | W13: 0 | X13: 0 | Y13: 0 | Z13: 0 | AA13: 0 | AB13: 2912 | AC13: 0 | AD13: 0 | AE13: 0 | AF13: 0 | AG13: 0 | AH13: 0 | AI13: 0 | AL13: 242.66667 | AM13: 2912
P14: 0 | Q14: 0 | R14: 0 | S14: 0 | T14: 0 | U14: 0 | V14: 0 | W14: 0 | X14: 0 | Y14: 0 | Z14: 0 | AA14: 0 | AB14: 0 | AC14: 0 | AD14: 0 | AE14: 0 | AF14: 0 | AG14: 0 | AH14: 0 | AI14: 0 | AL14: 0 | AM14: 0
P15: 0 | Q15: 0 | R15: 0 | S15: 0 | T15: 0 | U15: 0 | V15: 0 | W15: 0 | X15: 0 | Y15: 0 | Z15: 0 | AA15: 0 | AB15: 0 | AC15: 0 | AD15: 0 | AE15: 0 | AF15: 0 | AG15: 0 | AH15: 0 | AI15: 0 | AL15: 0 | AM15: 0
P16: 0 | Q16: 0 | R16: 0 | S16: 0 | T16: 0 | U16: 0 | V16: 0 | W16: 0 | X16: 0 | Y16: 0 | Z16: 0 | AA16: 0 | AB16: 0 | AC16: 0 | AD16: 0 | AE16: 0 | AF16: 0 | AG16: 0 | AH16: 0 | AI16: 0 | AL16: 0 | AM16: 0
P17: 0 | Q17: 0 | R17: 0 | S17: 0 | T17: 0 | U17: 0 | V17: 0 | W17: 0 | X17: 0 | Y17: 0 | Z17: 0 | AA17: 0 | AB17: 0 | AC17: 0 | AD17: 0 | AE17: 0 | AF17: 0 | AG17: 0 | AH17: 0 | AI17: 0 | AL17: 0 | AM17: 0
P18: 0 | Q18: 0 | R18: 0 | S18: 0 | T18: 0 | U18: 0 | V18: 0 | W18: 0 | X18: 0 | Y18: 0 | Z18: 0 | AA18: 0 | AB18: 0 | AC18: 0 | AD18: 0 | AE18: 0 | AF18: 0 | AG18: 0 | AH18: 0 | AI18: 0 | AL18: 0 | AM18: 0
P19: 0 | Q19: 0 | R19: 0 | S19: 0 | T19: 0 | U19: 0 | V19: 0 | W19: 0 | X19: 0 | Y19: 0 | Z19: 0 | AA19: 0 | AB19: 0 | AC19: 0 | AD19: 0 | AE19: 0 | AF19: 0 | AG19: 0 | AH19: 0 | AI19: 0 | AL19: 0 | AM19: 0
P20: 0 | Q20: 0 | R20: 0 | S20: 0 | T20: 0 | U20: 0 | V20: 0 | W20: 0 | X20: 0 | Y20: 0 | Z20: 0 | AA20: 0 | AB20: 0 | AC20: 0 | AD20: 0 | AE20: 0 | AF20: 0 | AG20: 0 | AH20: 0 | AI20: 0 | AL20: 0 | AM20: 0
P21: 0 | Q21: 0 | R21: 0 | S21: 0 | T21: 0 | U21: 0 | V21: 0 | W21: 0 | X21: 0 | Y21: 0 | Z21: 0 | AA21: 0 | AB21: 0 | AC21: 0 | AD21: 0 | AE21: 0 | AF21: 0 | AG21: 0 | AH21: 0 | AI21: 0 | AL21: 0 | AM21: 0
P22: 0 | Q22: 0 | R22: 0 | S22: 0 | T22: 0 | U22: 0 | V22: 0 | W22: 0 | X22: 0 | Y22: 0 | Z22: 0 | AA22: 0 | AB22: 0 | AC22: 0 | AD22: 0 | AE22: 0 | AF22: 0 | AG22: 0 | AH22: 0 | AI22: 0 | AL22: 0 | AM22: 0
B23: TOTAL | P23: 0 | Q23: 0 | R23: 0 | S23: 0 | T23: 0 | U23: 0 | V23: 0 | W23: 0 | X23: 0 | Y23: 0 | Z23: 0 | AA23: 0 | AB23: 0 | AC23: 0 | AD23: 0 | AE23: 0 | AF23: 0 | AG23: 0 | AH23: 0 | AI23: 0 | AJ23: {=_xlfn.LET(_xlpm.StartRow,MATCH(2,1/(F$6:F22="Start")),SUM(OFFSET($P$6,_xlpm.StartRow+1,0,ROW(F22)-_xlpm.StartRow-1,10)))} -> 4065.9933 | AK23: {=_xlfn.LET(_xlpm.StartRow,MATCH(2,1/(F$6:F22="Start")),SUM(OFFSET($Z$6,_xlpm.StartRow+1,0,ROW(F22)-_xlpm.StartRow-1,10)))} -> 48791.92 | AL23: 4065.9933 | AM23: 48791.92
P24: 0 | Q24: 0 | R24: 0 | S24: 0 | T24: 0 | U24: 0 | V24: 0 | W24: 0 | X24: 0 | Y24: 0 | Z24: 0 | AA24: 0 | AB24: 0 | AC24: 0 | AD24: 0 | AE24: 0 | AF24: 0 | AG24: 0 | AH24: 0 | AI24: 0 | AL24: 0 | AM24: 0
B25: Savings | F25: Start | G25: Start | H25: Start | I25: Start | J25: Start | K25: Start | L25: Start | M25: Start | N25: Start | O25: Start | P25: 0 | Q25: 0 | R25: 0 | S25: 0 | T25: 0 | U25: 0 | V25: 0 | W25: 0 | X25: 0 | Y25: 0 | Z25: 0 | AA25: 0 | AB25: 0 | AC25: 0 | AD25: 0 | AE25: 0 | AF25: 0 | AG25: 0 | AH25: 0 | AI25: 0 | AL25: 0 | AM25: 0
P26: 0 | Q26: 0 | R26: 0 | S26: 0 | T26: 0 | U26: 0 | V26: 0 | W26: 0 | X26: 0 | Y26: 0 | Z26: 0 | AA26: 0 | AB26: 0 | AC26: 0 | AD26: 0 | AE26: 0 | AF26: 0 | AG26: 0 | AH26: 0 | AI26: 0 | AL26: 0 | AM26: 0
P27: 0 | Q27: 0 | R27: 0 | S27: 0 | T27: 0 | U27: 0 | V27: 0 | W27: 0 | X27: 0 | Y27: 0 | Z27: 0 | AA27: 0 | AB27: 0 | AC27: 0 | AD27: 0 | AE27: 0 | AF27: 0 | AG27: 0 | AH27: 0 | AI27: 0 | AL27: 0 | AM27: 0
P28: 0 | Q28: 0 | R28: 0 | S28: 0 | T28: 0 | U28: 0 | V28: 0 | W28: 0 | X28: 0 | Y28: 0 | Z28: 0 | AA28: 0 | AB28: 0 | AC28: 0 | AD28: 0 | AE28: 0 | AF28: 0 | AG28: 0 | AH28: 0 | AI28: 0 | AL28: 0 | AM28: 0
P29: 0 | Q29: 0 | R29: 0 | S29: 0 | T29: 0 | U29: 0 | V29: 0 | W29: 0 | X29: 0 | Y29: 0 | Z29: 0 | AA29: 0 | AB29: 0 | AC29: 0 | AD29: 0 | AE29: 0 | AF29: 0 | AG29: 0 | AH29: 0 | AI29: 0 | AL29: 0 | AM29: 0
P30: 0 | Q30: 0 | R30: 0 | S30: 0 | T30: 0 | U30: 0 | V30: 0 | W30: 0 | X30: 0 | Y30: 0 | Z30: 0 | AA30: 0 | AB30: 0 | AC30: 0 | AD30: 0 | AE30: 0 | AF30: 0 | AG30: 0 | AH30: 0 | AI30: 0 | AL30: 0 | AM30: 0
P31: 0 | Q31: 0 | R31: 0 | S31: 0 | T31: 0 | U31: 0 | V31: 0 | W31: 0 | X31: 0 | Y31: 0 | Z31: 0 | AA31: 0 | AB31: 0 | AC31: 0 | AD31: 0 | AE31: 0 | AF31: 0 | AG31: 0 | AH31: 0 | AI31: 0 | AL31: 0 | AM31: 0
P32: 0 | Q32: 0 | R32: 0 | S32: 0 | T32: 0 | U32: 0 | V32: 0 | W32: 0 | X32: 0 | Y32: 0 | Z32: 0 | AA32: 0 | AB32: 0 | AC32: 0 | AD32: 0 | AE32: 0 | AF32: 0 | AG32: 0 | AH32: 0 | AI32: 0 | AL32: 0 | AM32: 0
P33: 0 | Q33: 0 | R33: 0 | S33: 0 | T33: 0 | U33: 0 | V33: 0 | W33: 0 | X33: 0 | Y33: 0 | Z33: 0 | AA33: 0 | AB33: 0 | AC33: 0 | AD33: 0 | AE33: 0 | AF33: 0 | AG33: 0 | AH33: 0 | AI33: 0 | AL33: 0 | AM33: 0
P34: 0 | Q34: 0 | R34: 0 | S34: 0 | T34: 0 | U34: 0 | V34: 0 | W34: 0 | X34: 0 | Y34: 0 | Z34: 0 | AA34: 0 | AB34: 0 | AC34: 0 | AD34: 0 | AE34: 0 | AF34: 0 | AG34: 0 | AH34: 0 | AI34: 0 | AL34: 0 | AM34: 0
P35: 0 | Q35: 0 | R35: 0 | S35: 0 | T35: 0 | U35: 0 | V35: 0 | W35: 0 | X35: 0 | Y35: 0 | Z35: 0 | AA35: 0 | AB35: 0 | AC35: 0 | AD35: 0 | AE35: 0 | AF35: 0 | AG35: 0 | AH35: 0 | AI35: 0 | AL35: 0 | AM35: 0
P36: 0 | Q36: 0 | R36: 0 | S36: 0 | T36: 0 | U36: 0 | V36: 0 | W36: 0 | X36: 0 | Y36: 0 | Z36: 0 | AA36: 0 | AB36: 0 | AC36: 0 | AD36: 0 | AE36: 0 | AF36: 0 | AG36: 0 | AH36: 0 | AI36: 0 | AL36: 0 | AM36: 0
P37: 0 | Q37: 0 | R37: 0 | S37: 0 | T37: 0 | U37: 0 | V37: 0 | W37: 0 | X37: 0 | Y37: 0 | Z37: 0 | AA37: 0 | AB37: 0 | AC37: 0 | AD37: 0 | AE37: 0 | AF37: 0 | AG37: 0 | AH37: 0 | AI37: 0 | AL37: 0 | AM37: 0
B38: TOTAL | P38: 0 | Q38: 0 | R38: 0 | S38: 0 | T38: 0 | U38: 0 | V38: 0 | W38: 0 | X38: 0 | Y38: 0 | Z38: 0 | AA38: 0 | AB38: 0 | AC38: 0 | AD38: 0 | AE38: 0 | AF38: 0 | AG38: 0 | AH38: 0 | AI38: 0 | AJ38: {=_xlfn.LET(_xlpm.StartRow,MATCH(2,1/(F$6:F37="Start")),SUM(OFFSET($P$6,_xlpm.StartRow+1,0,ROW(F37)-_xlpm.StartRow-7,10)))} -> 0 | AK38: {=_xlfn.LET(_xlpm.StartRow,MATCH(2,1/(F$6:F37="Start")),SUM(OFFSET($Z$6,_xlpm.StartRow+1,0,ROW(F37)-_xlpm.StartRow-7,10)))} -> 0 | AL38: 0 | AM38: 0
P39: 0 | Q39: 0 | R39: 0 | S39: 0 | T39: 0 | U39: 0 | V39: 0 | W39: 0 | X39: 0 | Y39: 0 | Z39: 0 | AA39: 0 | AB39: 0 | AC39: 0 | AD39: 0 | AE39: 0 | AF39: 0 | AG39: 0 | AH39: 0 | AI39: 0 | AL39: 0 | AM39: 0
B40: Transfers | F40: Start | G40: Start | H40: Start | I40: Start | J40: Start | K40: Start | L40: Start | M40: Start | N40: Start | O40: Start | P40: 0 | Q40: 0 | R40: 0 | S40: 0 | T40: 0 | U40: 0 | V40: 0 | W40: 0 | X40: 0 | Y40: 0 | Z40: 0 | AA40: 0 | AB40: 0 | AC40: 0 | AD40: 0 | AE40: 0 | AF40: 0 | AG40: 0 | AH40: 0 | AI40: 0 | AL40: 0 | AM40: 0
P41: 0 | Q41: 0 | R41: 0 | S41: 0 | T41: 0 | U41: 0 | V41: 0 | W41: 0 | X41: 0 | Y41: 0 | Z41: 0 | AA41: 0 | AB41: 0 | AC41: 0 | AD41: 0 | AE41: 0 | AF41: 0 | AG41: 0 | AH41: 0 | AI41: 0 | AL41: 0 | AM41: 0
B42: 1 | C42: month(s) | D42: 45629 | E42: Visa Platinum | F42: -229 | K42: 311 | P42: -229 | Q42: 0 | R42: 0 | S42: 0 | T42: 0 | U42: 311 | V42: 0 | W42: 0 | X42: 0 | Y42: 0 | Z42: -2748 | AA42: 0 | AB42: 0 | AC42: 0 | AD42: 0 | AE42: 3732 | AF42: 0 | AG42: 0 | AH42: 0 | AI42: 0 | AL42: 82 | AM42: 984
B43: 1 | C43: month(s) | D43: 45637 | E43: Viso Go | F43: -275 | L43: 146 | P43: -275 | Q43: 0 | R43: 0 | S43: 0 | T43: 0 | U43: 0 | V43: 146 | W43: 0 | X43: 0 | Y43: 0 | Z43: -3300 | AA43: 0 | AB43: 0 | AC43: 0 | AD43: 0 | AE43: 0 | AF43: 1752 | AG43: 0 | AH43: 0 | AI43: 0 | AL43: -129 | AM43: -1548
B44: 1 | C44: month(s) | D44: 46050 | E44: Costco Citi | F44: -140 | O44: 140 | P44: -140 | Q44: 0 | R44: 0 | S44: 0 | T44: 0 | U44: 0 | V44: 0 | W44: 0 | X44: 0 | Y44: 140 | Z44: -1680 | AA44: 0 | AB44: 0 | AC44: 0 | AD44: 0 | AE44: 0 | AF44: 0 | AG44: 0 | AH44: 0 | AI44: 1680 | AL44: 0 | AM44: 0
...

Sheet Forecast
B1: TRANSACTION FORECAST
B2: x | C2: Use this sheet to balance your checkbook. The forecast is calculated off the starting date and balances at the top. (All transactions before the starting date will be ommitted) If you need to adjust the date or dollar amount of a transaction, add it to the Manual Adjustments section and make sure to skip the corresponding transaction by selecting the checkmark in the Calculated Forecast section. Once all calculated transactions before a given date have been processed, you can adjust the starting date - when you change the start date, the transactions will re-calculate so you will have to clear the manual adjustments and skipped transactions as needed.
B3: x
B4: x
B5: x
B6: Skip | C6: Description | D6: Date | E6: =IF('Monthly budget'!F6<>"",'Monthly budget'!F6,"") -> US Bank | F6: =IF('Monthly budget'!G6<>"",'Monthly budget'!G6,"") -> Wells Fargo | G6: =IF('Monthly budget'!H6<>"",'Monthly budget'!H6,"") -> ADP | H6: =IF('Monthly budget'!I6<>"",'Monthly budget'!I6,"") -> Marcus | I6: =IF('Monthly budget'!J6<>"",'Monthly budget'!J6,"") -> T.Rowe Price | J6: =IF('Monthly budget'!K6<>"",'Monthly budget'!K6,"") -> Platinum | K6: =IF('Monthly budget'!L6<>"",'Monthly budget'!L6,"") -> Visa Go | L6: Costco | N6: =IF('Monthly budget'!O6<>"",'Monthly budget'!O6,"") | O6: DateHelper | P6: =E6&"Helper" -> US BankHelper | Q6: =F6&"Helper" -> Wells FargoHelper | R6: =G6&"Helper" -> ADPHelper | S6: =H6&"Helper" -> MarcusHelper | T6: =I6&"Helper" -> T.Rowe PriceHelper | U6: =J6&"Helper" -> PlatinumHelper | V6: =K6&"Helper" -> Visa GoHelper | W6: =L6&"Helper" -> CostcoHelper | ... Y6: =N6&"Helper" -> Helper
B7: FALSE | C7: Starting balance | D7: 46081 | E7: 3775.81 | F7: 6067.9 | G7: 23232.39 | H7: 114.43 | I7: 12062.04 | J7: -6311.05 | K7: -8503.82 | L7: -4271.75 | O7: {=IFERROR(VLOOKUP(DescList,$C$29:$D$1011,2,FALSE),"")} | P7: {=IFERROR(VLOOKUP(DescList,$C$29:$N$1011,COLUMN(P6)-12,FALSE),"")} | Q7: {=IFERROR(VLOOKUP(DescList,$C$29:$N$1011,COLUMN(Q6)-12,FALSE),"")} | R7: {=IFERROR(VLOOKUP(DescList,$C$29:$N$1011,COLUMN(R6)-12,FALSE),"")} | S7: {=IFERROR(VLOOKUP(DescList,$C$29:$N$1011,COLUMN(S6)-12,FALSE),"")} | T7: {=IFERROR(VLOOKUP(DescList,$C$29:$N$1011,COLUMN(T6)-12,FALSE),"")} | U7: {=IFERROR(VLOOKUP(DescList,$C$29:$N$1011,COLUMN(U6)-12,FALSE),"")} | V7: {=IFERROR(VLOOKUP(DescList,$C$29:$N$1011,COLUMN(V6)-12,FALSE),"")} | W7: {=IFERROR(VLOOKUP(DescList,$C$29:$N$1011,COLUMN(W6)-12,FALSE),"")} | ... Y7: {=IFERROR(VLOOKUP(DescList,$C$29:$N$1011,COLUMN(Y6)-12,FALSE),"")}
B9: Manual Adjustments
B11: FALSE
B12: FALSE
B13: FALSE
B14: FALSE
B15: FALSE
B16: FALSE
B17: FALSE
B18: FALSE
B19: FALSE
B20: FALSE
B21: FALSE
B22: FALSE
... B25: FALSE
B26: Calculated Forecast
B27: Skip
B29: FALSE | C29: {=_xlfn.LET(_xlpm.data,_xlfn._xlws.SORT(_xlfn.HSTACK(_xlfn.TOCOL(_xlfn.ANCHORARRAY('Helper - All dates'!B2)&IF(_xlfn.HSTACK(_xlfn.ANCHORARRAY('Helper - All dates'!E2),_xlfn.ANCHORARRAY('Helper - All dates'!F2))=FALSE,"","")),_xlfn.TOCOL(_xlfn.HSTACK(_xlfn.ANCHORARRAY('Helper - All dates'!E2),_xlfn.ANCHORARRAY('Helper - All dates'!F2)))),2),_xlfn._xlws.FILTER(_xlpm.data,_xlfn.CHOOSECOLS(_xlpm.data,2)<EDATE('Helper - All dates'!$A$2,24)))} -> Costco Citi | D29: 46081 | E29: =IF($C29<>"",VLOOKUP($C29,'Monthly budget'!$E$8:$O$86,COLUMN()-3,FALSE),0) -> -140 | F29: =IF($C29<>"",VLOOKUP($C29,'Monthly budget'!$E$8:$O$86,COLUMN()-3,FALSE),0) -> 0 | G29: =IF($C29<>"",VLOOKUP($C29,'Monthly budget'!$E$8:$O$86,COLUMN()-3,FALSE),0) -> 0 | H29: =IF($C29<>"",VLOOKUP($C29,'Monthly budget'!$E$8:$O$86,COLUMN()-3,FALSE),0) -> 0 | I29: =IF($C29<>"",VLOOKUP($C29,'Monthly budget'!$E$8:$O$86,COLUMN()-3,FALSE),0) -> 0 | J29: =IF($C29<>"",VLOOKUP($C29,'Monthly budget'!$E$8:$O$86,COLUMN()-3,FALSE),0) -> 0 | K29: =IF($C29<>"",VLOOKUP($C29,'Monthly budget'!$E$8:$O$86,COLUMN()-3,FALSE),0) -> 0 | L29: =IF($C29<>"",VLOOKUP($C29,'Monthly budget'!$E$8:$O$86,COLUMN()-3,FALSE),0) -> 0 | ... N29: =IF($C29<>"",VLOOKUP($C29,'Monthly budget'!$E$8:$O$86,COLUMN()-3,FALSE),0) -> 140
B30: TRUE | C30: Kulo Transfer | D30: 46081 | E30: =IF($C30<>"",VLOOKUP($C30,'Monthly budget'!$E$8:$O$86,COLUMN()-3,FALSE),0) -> 1050 | F30: =IF($C30<>"",VLOOKUP($C30,'Monthly budget'!$E$8:$O$86,COLUMN()-3,FALSE),0) -> 0 | G30: =IF($C30<>"",VLOOKUP($C30,'Monthly budget'!$E$8:$O$86,COLUMN()-3,FALSE),0) -> 0 | H30: =IF($C30<>"",VLOOKUP($C30,'Monthly budget'!$E$8:$O$86,COLUMN()-3,FALSE),0) -> 0 | I30: =IF($C30<>"",VLOOKUP($C30,'Monthly budget'!$E$8:$O$86,COLUMN()-3,FALSE),0) -> 0 | J30: =IF($C30<>"",VLOOKUP($C30,'Monthly budget'!$E$8:$O$86,COLUMN()-3,FALSE),0) -> 0 | K30: =IF($C30<>"",VLOOKUP($C30,'Monthly budget'!$E$8:$O$86,COLUMN()-3,FALSE),0) -> 0 | L30: =IF($C30<>"",VLOOKUP($C30,'Monthly budget'!$E$8:$O$86,COLUMN()-3,FALSE),0) -> 0 | ... N30: =IF($C30<>"",VLOOKUP($C30,'Monthly budget'!$E$8:$O$86,COLUMN()-3,FALSE),0) -> 0
B31: FALSE | C31: Kulo SDGE | D31: 46081 | E31: =IF($C31<>"",VLOOKUP($C31,'Monthly budget'!$E$8:$O$86,COLUMN()-3,FALSE),0) -> -82 | F31: =IF($C31<>"",VLOOKUP($C31,'Monthly budget'!$E$8:$O$86,COLUMN()-3,FALSE),0) -> 0 | G31: =IF($C31<>"",VLOOKUP($C31,'Monthly budget'!$E$8:$O$86,COLUMN()-3,FALSE),0) -> 0 | H31: =IF($C31<>"",VLOOKUP($C31,'Monthly budget'!$E$8:$O$86,COLUMN()-3,FALSE),0) -> 0 | I31: =IF($C31<>"",VLOOKUP($C31,'Monthly budget'!$E$8:$O$86,COLUMN()-3,FALSE),0) -> 0 | J31: =IF($C31<>"",VLOOKUP($C31,'Monthly budget'!$E$8:$O$86,COLUMN()-3,FALSE),0) -> 0 | K31: =IF($C31<>"",VLOOKUP($C31,'Monthly budget'!$E$8:$O$86,COLUMN()-3,FALSE),0) -> 0 | L31: =IF($C31<>"",VLOOKUP($C31,'Monthly budget'!$E$8:$O$86,COLUMN()-3,FALSE),0) -> 0 | ... N31: =IF($C31<>"",VLOOKUP($C31,'Monthly budget'!$E$8:$O$86,COLUMN()-3,FALSE),0) -> 0
B32: FALSE | C32: Groceries | D32: 46081 | E32: =IF($C32<>"",VLOOKUP($C32,'Monthly budget'!$E$8:$O$86,COLUMN()-3,FALSE),0) -> 0 | F32: =IF($C32<>"",VLOOKUP($C32,'Monthly budget'!$E$8:$O$86,COLUMN()-3,FALSE),0) -> -200 | G32: =IF($C32<>"",VLOOKUP($C32,'Monthly budget'!$E$8:$O$86,COLUMN()-3,FALSE),0) -> 0 | H32: =IF($C32<>"",VLOOKUP($C32,'Monthly budget'!$E$8:$O$86,COLUMN()-3,FALSE),0) -> 0 | I32: =IF($C32<>"",VLOOKUP($C32,'Monthly budget'!$E$8:$O$86,COLUMN()-3,FALSE),0) -> 0 | J32: =IF($C32<>"",VLOOKUP($C32,'Monthly budget'!$E$8:$O$86,COLUMN()-3,FALSE),0) -> 0 | K32: =IF($C32<>"",VLOOKUP($C32,'Monthly budget'!$E$8:$O$86,COLUMN()-3,FALSE),0) -> 0 | L32: =IF($C32<>"",VLOOKUP($C32,'Monthly budget'!$E$8:$O$86,COLUMN()-3,FALSE),0) -> 0 | ... N32: =IF($C32<>"",VLOOKUP($C32,'Monthly budget'!$E$8:$O$86,COLUMN()-3,FALSE),0) -> 0
B33: FALSE | C33: Food & Drinks | D33: 46081 | E33: =IF($C33<>"",VLOOKUP($C33,'Monthly budget'!$E$8:$O$86,COLUMN()-3,FALSE),0) -> 0 | F33: =IF($C33<>"",VLOOKUP($C33,'Monthly budget'!$E$8:$O$86,COLUMN()-3,FALSE),0) -> -200 | G33: =IF($C33<>"",VLOOKUP($C33,'Monthly budget'!$E$8:$O$86,COLUMN()-3,FALSE),0) -> 0 | H33: =IF($C33<>"",VLOOKUP($C33,'Monthly budget'!$E$8:$O$86,COLUMN()-3,FALSE),0) -> 0 | I33: =IF($C33<>"",VLOOKUP($C33,'Monthly budget'!$E$8:$O$86,COLUMN()-3,FALSE),0) -> 0 | J33: =IF($C33<>"",VLOOKUP($C33,'Monthly budget'!$E$8:$O$86,COLUMN()-3,FALSE),0) -> 0 | K33: =IF($C33<>"",VLOOKUP($C33,'Monthly budget'!$E$8:$O$86,COLUMN()-3,FALSE),0) -> 0 | L33: =IF($C33<>"",VLOOKUP($C33,'Monthly budget'!$E$8:$O$86,COLUMN()-3,FALSE),0) -> 0 | ... N33: =IF($C33<>"",VLOOKUP($C33,'Monthly budget'!$E$8:$O$86,COLUMN()-3,FALSE),0) -> 0
B34: FALSE | C34: SDGE | D34: 46081 | E34: =IF($C34<>"",VLOOKUP($C34,'Monthly budget'!$E$8:$O$86,COLUMN()-3,FALSE),0) -> -84 | F34: =IF($C34<>"",VLOOKUP($C34,'Monthly budget'!$E$8:$O$86,COLUMN()-3,FALSE),0) -> 0 | G34: =IF($C34<>"",VLOOKUP($C34,'Monthly budget'!$E$8:$O$86,COLUMN()-3,FALSE),0) -> 0 | H34: =IF($C34<>"",VLOOKUP($C34,'Monthly budget'!$E$8:$O$86,COLUMN()-3,FALSE),0) -> 0 | I34: =IF($C34<>"",VLOOKUP($C34,'Monthly budget'!$E$8:$O$86,COLUMN()-3,FALSE),0) -> 0 | J34: =IF($C34<>"",VLOOKUP($C34,'Monthly budget'!$E$8:$O$86,COLUMN()-3,FALSE),0) -> 0 | K34: =IF($C34<>"",VLOOKUP($C34,'Monthly budget'!$E$8:$O$86,COLUMN()-3,FALSE),0) -> 0 | L34: =IF($C34<>"",VLOOKUP($C34,'Monthly budget'!$E$8:$O$86,COLUMN()-3,FALSE),0) -> 0 | ... N34: =IF($C34<>"",VLOOKUP($C34,'Monthly budget'!$E$8:$O$86,COLUMN()-3,FALSE),0) -> 0
B35: FALSE | C35: Prime Ad-Free | D35: 46081 | E35: =IF($C35<>"",VLOOKUP($C35,'Monthly budget'!$E$8:$O$86,COLUMN()-3,FALSE),0) -> -2.99 | F35: =IF($C35<>"",VLOOKUP($C35,'Monthly budget'!$E$8:$O$86,COLUMN()-3,FALSE),0) -> 0 | G35: =IF($C35<>"",VLOOKUP($C35,'Monthly budget'!$E$8:$O$86,COLUMN()-3,FALSE),0) -> 0 | H35: =IF($C35<>"",VLOOKUP($C35,'Monthly budget'!$E$8:$O$86,COLUMN()-3,FALSE),0) -> 0 | I35: =IF($C35<>"",VLOOKUP($C35,'Monthly budget'!$E$8:$O$86,COLUMN()-3,FALSE),0) -> 0 | J35: =IF($C35<>"",VLOOKUP($C35,'Monthly budget'!$E$8:$O$86,COLUMN()-3,FALSE),0) -> 0 | K35: =IF($C35<>"",VLOOKUP($C35,'Monthly budget'!$E$8:$O$86,COLUMN()-3,FALSE),0) -> 0 | L35: =IF($C35<>"",VLOOKUP($C35,'Monthly budget'!$E$8:$O$86,COLUMN()-3,FALSE),0) -> 0 | ... N35: =IF($C35<>"",VLOOKUP($C35,'Monthly budget'!$E$8:$O$86,COLUMN()-3,FALSE),0) -> 0
B36: FALSE | C36: Disability | D36: 46082 | E36: =IF($C36<>"",VLOOKUP($C36,'Monthly budget'!$E$8:$O$86,COLUMN()-3,FALSE),0) -> 0 | F36: =IF($C36<>"",VLOOKUP($C36,'Monthly budget'!$E$8:$O$86,COLUMN()-3,FALSE),0) -> 356.66 | G36: =IF($C36<>"",VLOOKUP($C36,'Monthly budget'!$E$8:$O$86,COLUMN()-3,FALSE),0) -> 0 | H36: =IF($C36<>"",VLOOKUP($C36,'Monthly budget'!$E$8:$O$86,COLUMN()-3,FALSE),0) -> 0 | I36: =IF($C36<>"",VLOOKUP($C36,'Monthly budget'!$E$8:$O$86,COLUMN()-3,FALSE),0) -> 0 | J36: =IF($C36<>"",VLOOKUP($C36,'Monthly budget'!$E$8:$O$86,COLUMN()-3,FALSE),0) -> 0 | K36: =IF($C36<>"",VLOOKUP($C36,'Monthly budget'!$E$8:$O$86,COLUMN()-3,FALSE),0) -> 0 | L36: =IF($C36<>"",VLOOKUP($C36,'Monthly budget'!$E$8:$O$86,COLUMN()-3,FALSE),0) -> 0 | ... N36: =IF($C36<>"",VLOOKUP($C36,'Monthly budget'!$E$8:$O$86,COLUMN()-3,FALSE),0) -> 0
B37: FALSE | C37: Kulo Rent | D37: 46082 | E37: =IF($C37<>"",VLOOKUP($C37,'Monthly budget'!$E$8:$O$86,COLUMN()-3,FALSE),0) -> -959 | F37: =IF($C37<>"",VLOOKUP($C37,'Monthly budget'!$E$8:$O$86,COLUMN()-3,FALSE),0) -> 0 | G37: =IF($C37<>"",VLOOKUP($C37,'Monthly budget'!$E$8:$O$86,COLUMN()-3,FALSE),0) -> 0 | H37: =IF($C37<>"",VLOOKUP($C37,'Monthly budget'!$E$8:$O$86,COLUMN()-3,FALSE),0) -> 0 | I37: =IF($C37<>"",VLOOKUP($C37,'Monthly budget'!$E$8:$O$86,COLUMN()-3,FALSE),0) -> 0 | J37: =IF($C37<>"",VLOOKUP($C37,'Monthly budget'!$E$8:$O$86,COLUMN()-3,FALSE),0) -> 0 | K37: =IF($C37<>"",VLOOKUP($C37,'Monthly budget'!$E$8:$O$86,COLUMN()-3,FALSE),0) -> 0 | L37: =IF($C37<>"",VLOOKUP($C37,'Monthly budget'!$E$8:$O$86,COLUMN()-3,FALSE),0) -> 0 | ... N37: =IF($C37<>"",VLOOKUP($C37,'Monthly budget'!$E$8:$O$86,COLUMN()-3,FALSE),0) -> 0
B38: FALSE | C38: Rent | D38: 46082 | E38: =IF($C38<>"",VLOOKUP($C38,'Monthly budget'!$E$8:$O$86,COLUMN()-3,FALSE),0) -> -1277.97 | F38: =IF($C38<>"",VLOOKUP($C38,'Monthly budget'!$E$8:$O$86,COLUMN()-3,FALSE),0) -> 0 | G38: =IF($C38<>"",VLOOKUP($C38,'Monthly budget'!$E$8:$O$86,COLUMN()-3,FALSE),0) -> 0 | H38: =IF($C38<>"",VLOOKUP($C38,'Monthly budget'!$E$8:$O$86,COLUMN()-3,FALSE),0) -> 0 | I38: =IF($C38<>"",VLOOKUP($C38,'Monthly budget'!$E$8:$O$86,COLUMN()-3,FALSE),0) -> 0 | J38: =IF($C38<>"",VLOOKUP($C38,'Monthly budget'!$E$8:$O$86,COLUMN()-3,FALSE),0) -> 0 | K38: =IF($C38<>"",VLOOKUP($C38,'Monthly budget'!$E$8:$O$86,COLUMN()-3,FALSE),0) -> 0 | L38: =IF($C38<>"",VLOOKUP($C38,'Monthly budget'!$E$8:$O$86,COLUMN()-3,FALSE),0) -> 0 | ... N38: =IF($C38<>"",VLOOKUP($C38,'Monthly budget'!$E$8:$O$86,COLUMN()-3,FALSE),0) -> 0
B39: FALSE | C39: Visa Platinum | D39: 46084 | E39: =IF($C39<>"",VLOOKUP($C39,'Monthly budget'!$E$8:$O$86,COLUMN()-3,FALSE),0) -> -229 | F39: =IF($C39<>"",VLOOKUP($C39,'Monthly budget'!$E$8:$O$86,COLUMN()-3,FALSE),0) -> 0 | G39: =IF($C39<>"",VLOOKUP($C39,'Monthly budget'!$E$8:$O$86,COLUMN()-3,FALSE),0) -> 0 | H39: =IF($C39<>"",VLOOKUP($C39,'Monthly budget'!$E$8:$O$86,COLUMN()-3,FALSE),0) -> 0 | I39: =IF($C39<>"",VLOOKUP($C39,'Monthly budget'!$E$8:$O$86,COLUMN()-3,FALSE),0) -> 0 | J39: =IF($C39<>"",VLOOKUP($C39,'Monthly budget'!$E$8:$O$86,COLUMN()-3,FALSE),0) -> 311 | K39: =IF($C39<>"",VLOOKUP($C39,'Monthly budget'!$E$8:$O$86,COLUMN()-3,FALSE),0) -> 0 | L39: =IF($C39<>"",VLOOKUP($C39,'Monthly budget'!$E$8:$O$86,COLUMN()-3,FALSE),0) -> 0 | ... N39: =IF($C39<>"",VLOOKUP($C39,'Monthly budget'!$E$8:$O$86,COLUMN()-3,FALSE),0) -> 0
B40: FALSE | C40: Kulo Internet | D40: 46086 | E40: =IF($C40<>"",VLOOKUP($C40,'Monthly budget'!$E$8:$O$86,COLUMN()-3,FALSE),0) -> -28 | F40: =IF($C40<>"",VLOOKUP($C40,'Monthly budget'!$E$8:$O$86,COLUMN()-3,FALSE),0) -> 0 | G40: =IF($C40<>"",VLOOKUP($C40,'Monthly budget'!$E$8:$O$86,COLUMN()-3,FALSE),0) -> 0 | H40: =IF($C40<>"",VLOOKUP($C40,'Monthly budget'!$E$8:$O$86,COLUMN()-3,FALSE),0) -> 0 | I40: =IF($C40<>"",VLOOKUP($C40,'Monthly budget'!$E$8:$O$86,COLUMN()-3,FALSE),0) -> 0 | J40: =IF($C40<>"",VLOOKUP($C40,'Monthly budget'!$E$8:$O$86,COLUMN()-3,FALSE),0) -> 0 | K40: =IF($C40<>"",VLOOKUP($C40,'Monthly budget'!$E$8:$O$86,COLUMN()-3,FALSE),0) -> 0 | L40: =IF($C40<>"",VLOOKUP($C40,'Monthly budget'!$E$8:$O$86,COLUMN()-3,FALSE),0) -> 0 | ... N40: =IF($C40<>"",VLOOKUP($C40,'Monthly budget'!$E$8:$O$86,COLUMN()-3,FALSE),0) -> 0
B41: FALSE | C41: Cese Phone | D41: 46086 | E41: =IF($C41<>"",VLOOKUP($C41,'Monthly budget'!$E$8:$O$86,COLUMN()-3,FALSE),0) -> -142 | F41: =IF($C41<>"",VLOOKUP($C41,'Monthly budget'!$E$8:$O$86,COLUMN()-3,FALSE),0) -> 0 | G41: =IF($C41<>"",VLOOKUP($C41,'Monthly budget'!$E$8:$O$86,COLUMN()-3,FALSE),0) -> 0 | H41: =IF($C41<>"",VLOOKUP($C41,'Monthly budget'!$E$8:$O$86,COLUMN()-3,FALSE),0) -> 0 | I41: =IF($C41<>"",VLOOKUP($C41,'Monthly budget'!$E$8:$O$86,COLUMN()-3,FALSE),0) -> 0 | J41: =IF($C41<>"",VLOOKUP($C41,'Monthly budget'!$E$8:$O$86,COLUMN()-3,FALSE),0) -> 0 | K41: =IF($C41<>"",VLOOKUP($C41,'Monthly budget'!$E$8:$O$86,COLUMN()-3,FALSE),0) -> 0 | L41: =IF($C41<>"",VLOOKUP($C41,'Monthly budget'!$E$8:$O$86,COLUMN()-3,FALSE),0) -> 0 | ... N41: =IF($C41<>"",VLOOKUP($C41,'Monthly budget'!$E$8:$O$86,COLUMN()-3,FALSE),0) -> 0
... B800: FALSE | C800: Tidal | D800: 46810 | E800: =IF($C800<>"",VLOOKUP($C800,'Monthly budget'!$E$8:$O$86,COLUMN()-3,FALSE),0) -> -10.99 | F800: =IF($C800<>"",VLOOKUP($C800,'Monthly budget'!$E$8:$O$86,COLUMN()-3,FALSE),0) -> 0 | G800: =IF($C800<>"",VLOOKUP($C800,'Monthly budget'!$E$8:$O$86,COLUMN()-3,FALSE),0) -> 0 | H800: =IF($C800<>"",VLOOKUP($C800,'Monthly budget'!$E$8:$O$86,COLUMN()-3,FALSE),0) -> 0 | I800: =IF($C800<>"",VLOOKUP($C800,'Monthly budget'!$E$8:$O$86,COLUMN()-3,FALSE),0) -> 0 | J800: =IF($C800<>"",VLOOKUP($C800,'Monthly budget'!$E$8:$O$86,COLUMN()-3,FALSE),0) -> 0 | K800: =IF($C800<>"",VLOOKUP($C800,'Monthly budget'!$E$8:$O$86,COLUMN()-3,FALSE),0) -> 0 | L800: =IF($C800<>"",VLOOKUP($C800,'Monthly budget'!$E$8:$O$86,COLUMN()-3,FALSE),0) -> 0 | ... N800: =IF($C800<>"",VLOOKUP($C800,'Monthly budget'!$E$8:$O$86,COLUMN()-3,FALSE),0) -> 0
B801: FALSE | E801: =IF($C801<>"",VLOOKUP($C801,'Monthly budget'!$E$8:$O$86,COLUMN()-3,FALSE),0) -> 0 | F801: =IF($C801<>"",VLOOKUP($C801,'Monthly budget'!$E$8:$O$86,COLUMN()-3,FALSE),0) -> 0 | G801: =IF($C801<>"",VLOOKUP($C801,'Monthly budget'!$E$8:$O$86,COLUMN()-3,FALSE),0) -> 0 | H801: =IF($C801<>"",VLOOKUP($C801,'Monthly budget'!$E$8:$O$86,COLUMN()-3,FALSE),0) -> 0 | I801: =IF($C801<>"",VLOOKUP($C801,'Monthly budget'!$E$8:$O$86,COLUMN()-3,FALSE),0) -> 0 | J801: =IF($C801<>"",VLOOKUP($C801,'Monthly budget'!$E$8:$O$86,COLUMN()-3,FALSE),0) -> 0 | K801: =IF($C801<>"",VLOOKUP($C801,'Monthly budget'!$E$8:$O$86,COLUMN()-3,FALSE),0) -> 0 | L801: =IF($C801<>"",VLOOKUP($C801,'Monthly budget'!$E$8:$O$86,COLUMN()-3,FALSE),0) -> 0 | ... N801: =IF($C801<>"",VLOOKUP($C801,'Monthly budget'!$E$8:$O$86,COLUMN()-3,FALSE),0) -> 0
B802: FALSE | E802: =IF($C802<>"",VLOOKUP($C802,'Monthly budget'!$E$8:$O$86,COLUMN()-3,FALSE),0) -> 0 | F802: =IF($C802<>"",VLOOKUP($C802,'Monthly budget'!$E$8:$O$86,COLUMN()-3,FALSE),0) -> 0 | G802: =IF($C802<>"",VLOOKUP($C802,'Monthly budget'!$E$8:$O$86,COLUMN()-3,FALSE),0) -> 0 | H802: =IF($C802<>"",VLOOKUP($C802,'Monthly budget'!$E$8:$O$86,COLUMN()-3,FALSE),0) -> 0 | I802: =IF($C802<>"",VLOOKUP($C802,'Monthly budget'!$E$8:$O$86,COLUMN()-3,FALSE),0) -> 0 | J802: =IF($C802<>"",VLOOKUP($C802,'Monthly budget'!$E$8:$O$86,COLUMN()-3,FALSE),0) -> 0 | K802: =IF($C802<>"",VLOOKUP($C802,'Monthly budget'!$E$8:$O$86,COLUMN()-3,FALSE),0) -> 0 | L802: =IF($C802<>"",VLOOKUP($C802,'Monthly budget'!$E$8:$O$86,COLUMN()-3,FALSE),0) -> 0 | ... N802: =IF($C802<>"",VLOOKUP($C802,'Monthly budget'!$E$8:$O$86,COLUMN()-3,FALSE),0) -> 0
B803: FALSE | E803: =IF($C803<>"",VLOOKUP($C803,'Monthly budget'!$E$8:$O$86,COLUMN()-3,FALSE),0) -> 0 | F803: =IF($C803<>"",VLOOKUP($C803,'Monthly budget'!$E$8:$O$86,COLUMN()-3,FALSE),0) -> 0 | G803: =IF($C803<>"",VLOOKUP($C803,'Monthly budget'!$E$8:$O$86,COLUMN()-3,FALSE),0) -> 0 | H803: =IF($C803<>"",VLOOKUP($C803,'Monthly budget'!$E$8:$O$86,COLUMN()-3,FALSE),0) -> 0 | I803: =IF($C803<>"",VLOOKUP($C803,'Monthly budget'!$E$8:$O$86,COLUMN()-3,FALSE),0) -> 0 | J803: =IF($C803<>"",VLOOKUP($C803,'Monthly budget'!$E$8:$O$86,COLUMN()-3,FALSE),0) -> 0 | K803: =IF($C803<>"",VLOOKUP($C803,'Monthly budget'!$E$8:$O$86,COLUMN()-3,FALSE),0) -> 0 | L803: =IF($C803<>"",VLOOKUP($C803,'Monthly budget'!$E$8:$O$86,COLUMN()-3,FALSE),0) -> 0 | ... N803: =IF($C803<>"",VLOOKUP($C803,'Monthly budget'!$E$8:$O$86,COLUMN()-3,FALSE),0) -> 0
...

Sheet Dashboard
B1: Dashboard
B2: x | C2: Use this sheet to identify trends and trouble spots in your forecasted budget. The chart at the top shows each account over time. You can select which accounts to display using the slicer on the right and the date range using the timeline below the chart. Please note, the chart uses the average for each acocunt when summarizining the values so the chart will not show the effect of each transaction when multiple occur on the same day. The table below the chart will identify negative checking and savings balances, the bottom 10 balances for each account, and the lowest single balance for each account. Click on the chart and go to PivotChart Analyze > Refresh > Refresh All to update the accounts and balances in the chart.
B3: x
B4: x
B5: x
B34: Transactions | C34: Dates | D34: Checking | E34: Credit | F34: Savings | G34: Net Worth | H34: ="Account 1 "&'Monthly budget'!F6 -> Account 1 US Bank | I34: ="Account 2 "&'Monthly budget'!G6 -> Account 2 Wells Fargo | J34: ="Account 3 "&'Monthly budget'!H6 -> Account 3 ADP | K34: ="Account 4 "&'Monthly budget'!I6 -> Account 4 Marcus | L34: ="Account 5 "&'Monthly budget'!J6 -> Account 5 T.Rowe Price | M34: ="Account 6 "&'Monthly budget'!K6 -> Account 6 Platinum | N34: ="Account 7 "&'Monthly budget'!L6 -> Account 7 Visa Go | O34: ="Account 8 "&'Monthly budget'!M6 -> Account 8 CareCredit | P34: ="Account 9 "&'Monthly budget'!N6 -> Account 9 Costco | Q34: ="Account 10 "&'Monthly budget'!O6 -> Account 10
B35: {=_xlfn.CHOOSECOLS(_xlfn._xlws.SORT(_xlfn._xlws.FILTER(Forecast!B:O,(Forecast!B:B=FALSE)*(Forecast!C:C<>"")),3),2)} -> Starting balance | C35: {=_xlfn.CHOOSECOLS(_xlfn._xlws.SORT(_xlfn._xlws.FILTER(Forecast!B:O,(Forecast!B:B=FALSE)*(Forecast!C:C<>"")),3),3)} -> 46081 | D35: {=_xlfn.BYROW(_xlfn.HSTACK(_xlfn.ANCHORARRAY(H35):_xlfn.ANCHORARRAY(Q35)),_xlfn.LAMBDA(_xlpm.a,SUMPRODUCT(--('Monthly budget'!$F$7:$O$7="Checking"),_xlpm.a)))} -> 9843.71 | E35: {=_xlfn.BYROW(_xlfn.HSTACK(_xlfn.ANCHORARRAY(H35):_xlfn.ANCHORARRAY(Q35)),_xlfn.LAMBDA(_xlpm.a,SUMPRODUCT(--('Monthly budget'!$F$7:$O$7="Credit"),_xlpm.a)))} -> -19086.62 | F35: {=_xlfn.BYROW(_xlfn.HSTACK(_xlfn.ANCHORARRAY(H35):_xlfn.ANCHORARRAY(Q35)),_xlfn.LAMBDA(_xlpm.a,SUMPRODUCT(--('Monthly budget'!$F$7:$O$7="Savings"),_xlpm.a)))} -> 35408.86 | G35: {=_xlfn.BYROW(_xlfn.HSTACK(_xlfn.ANCHORARRAY(H35):_xlfn.ANCHORARRAY(Q35)),_xlfn.LAMBDA(_xlpm.a,SUM(_xlpm.a)))} -> 26165.95 | H35: {=_xlfn.SCAN(0,_xlfn.CHOOSECOLS(_xlfn._xlws.SORT(_xlfn._xlws.FILTER(Forecast!B:O,(Forecast!B:B=FALSE)*(Forecast!C:C<>"")),3),4),_xlfn.LAMBDA(_xlpm.a,_xlpm.v,_xlpm.a+_xlpm.v))} -> 3775.81 | I35: {=_xlfn.SCAN(0,_xlfn.CHOOSECOLS(_xlfn._xlws.SORT(_xlfn._xlws.FILTER(Forecast!B:O,(Forecast!B:B=FALSE)*(Forecast!C:C<>"")),3),5),_xlfn.LAMBDA(_xlpm.a,_xlpm.v,_xlpm.a+_xlpm.v))} -> 6067.9 | J35: {=_xlfn.SCAN(0,_xlfn.CHOOSECOLS(_xlfn._xlws.SORT(_xlfn._xlws.FILTER(Forecast!B:O,(Forecast!B:B=FALSE)*(Forecast!C:C<>"")),3),6),_xlfn.LAMBDA(_xlpm.a,_xlpm.v,_xlpm.a+_xlpm.v))} -> 23232.39 | K35: {=_xlfn.SCAN(0,_xlfn.CHOOSECOLS(_xlfn._xlws.SORT(_xlfn._xlws.FILTER(Forecast!B:O,(Forecast!B:B=FALSE)*(Forecast!C:C<>"")),3),7),_xlfn.LAMBDA(_xlpm.a,_xlpm.v,_xlpm.a+_xlpm.v))} -> 114.43 | L35: {=_xlfn.SCAN(0,_xlfn.CHOOSECOLS(_xlfn._xlws.SORT(_xlfn._xlws.FILTER(Forecast!B:O,(Forecast!B:B=FALSE)*(Forecast!C:C<>"")),3),8),_xlfn.LAMBDA(_xlpm.a,_xlpm.v,_xlpm.a+_xlpm.v))} -> 12062.04 | M35: {=_xlfn.SCAN(0,_xlfn.CHOOSECOLS(_xlfn._xlws.SORT(_xlfn._xlws.FILTER(Forecast!B:O,(Forecast!B:B=FALSE)*(Forecast!C:C<>"")),3),9),_xlfn.LAMBDA(_xlpm.a,_xlpm.v,_xlpm.a+_xlpm.v))} -> -6311.05 | N35: {=_xlfn.SCAN(0,_xlfn.CHOOSECOLS(_xlfn._xlws.SORT(_xlfn._xlws.FILTER(Forecast!B:O,(Forecast!B:B=FALSE)*(Forecast!C:C<>"")),3),10),_xlfn.LAMBDA(_xlpm.a,_xlpm.v,_xlpm.a+_xlpm.v))} -> -8503.82 | O35: {=_xlfn.SCAN(0,_xlfn.CHOOSECOLS(_xlfn._xlws.SORT(_xlfn._xlws.FILTER(Forecast!B:O,(Forecast!B:B=FALSE)*(Forecast!C:C<>"")),3),11),_xlfn.LAMBDA(_xlpm.a,_xlpm.v,_xlpm.a+_xlpm.v))} -> -4271.75 | P35: {=_xlfn.SCAN(0,_xlfn.CHOOSECOLS(_xlfn._xlws.SORT(_xlfn._xlws.FILTER(Forecast!B:O,(Forecast!B:B=FALSE)*(Forecast!C:C<>"")),3),12),_xlfn.LAMBDA(_xlpm.a,_xlpm.v,_xlpm.a+_xlpm.v))} -> 0 | Q35: {=_xlfn.SCAN(0,_xlfn.CHOOSECOLS(_xlfn._xlws.SORT(_xlfn._xlws.FILTER(Forecast!B:O,(Forecast!B:B=FALSE)*(Forecast!C:C<>"")),3),13),_xlfn.LAMBDA(_xlpm.a,_xlpm.v,_xlpm.a+_xlpm.v))} -> 0
B36: Costco Citi | C36: 46081 | D36: 9703.71 | E36: -19086.62 | F36: 35408.86 | G36: 26165.95 | H36: 3635.81 | I36: 6067.9 | J36: 23232.39 | K36: 114.43 | L36: 12062.04 | M36: -6311.05 | N36: -8503.82 | O36: -4271.75 | P36: 0 | Q36: 140
B37: Kulo SDGE | C37: 46081 | D37: 9621.71 | E37: -19086.62 | F37: 35408.86 | G37: 26083.95 | H37: 3553.81 | I37: 6067.9 | J37: 23232.39 | K37: 114.43 | L37: 12062.04 | M37: -6311.05 | N37: -8503.82 | O37: -4271.75 | P37: 0 | Q37: 140
B38: Groceries | C38: 46081 | D38: 9421.71 | E38: -19086.62 | F38: 35408.86 | G38: 25883.95 | H38: 3553.81 | I38: 5867.9 | J38: 23232.39 | K38: 114.43 | L38: 12062.04 | M38: -6311.05 | N38: -8503.82 | O38: -4271.75 | P38: 0 | Q38: 140
B39: Food & Drinks | C39: 46081 | D39: 9221.71 | E39: -19086.62 | F39: 35408.86 | G39: 25683.95 | H39: 3553.81 | I39: 5667.9 | J39: 23232.39 | K39: 114.43 | L39: 12062.04 | M39: -6311.05 | N39: -8503.82 | O39: -4271.75 | P39: 0 | Q39: 140
B40: SDGE | C40: 46081 | D40: 9137.71 | E40: -19086.62 | F40: 35408.86 | G40: 25599.95 | H40: 3469.81 | I40: 5667.9 | J40: 23232.39 | K40: 114.43 | L40: 12062.04 | M40: -6311.05 | N40: -8503.82 | O40: -4271.75 | P40: 0 | Q40: 140
B41: Prime Ad-Free | C41: 46081 | D41: 9134.72 | E41: -19086.62 | F41: 35408.86 | G41: 25596.96 | H41: 3466.82 | I41: 5667.9 | J41: 23232.39 | K41: 114.43 | L41: 12062.04 | M41: -6311.05 | N41: -8503.82 | O41: -4271.75 | P41: 0 | Q41: 140
B42: Disability | C42: 46082 | D42: 9491.38 | E42: -19086.62 | F42: 35408.86 | G42: 25953.62 | H42: 3466.82 | I42: 6024.56 | J42: 23232.39 | K42: 114.43 | L42: 12062.04 | M42: -6311.05 | N42: -8503.82 | O42: -4271.75 | P42: 0 | Q42: 140
B43: Kulo Rent | C43: 46082 | D43: 8532.38 | E43: -19086.62 | F43: 35408.86 | G43: 24994.62 | H43: 2507.82 | I43: 6024.56 | J43: 23232.39 | K43: 114.43 | L43: 12062.04 | M43: -6311.05 | N43: -8503.82 | O43: -4271.75 | P43: 0 | Q43: 140
B44: Rent | C44: 46082 | D44: 7254.41 | E44: -19086.62 | F44: 35408.86 | G44: 23716.65 | H44: 1229.85 | I44: 6024.56 | J44: 23232.39 | K44: 114.43 | L44: 12062.04 | M44: -6311.05 | N44: -8503.82 | O44: -4271.75 | P44: 0 | Q44: 140
B45: Visa Platinum | C45: 46084 | D45: 7025.41 | E45: -18775.62 | F45: 35408.86 | G45: 23798.65 | H45: 1000.85 | I45: 6024.56 | J45: 23232.39 | K45: 114.43 | L45: 12062.04 | M45: -6000.05 | N45: -8503.82 | O45: -4271.75 | P45: 0 | Q45: 140
B46: Kulo Internet | C46: 46086 | D46: 6997.41 | E46: -18775.62 | F46: 35408.86 | G46: 23770.65 | H46: 972.85 | I46: 6024.56 | J46: 23232.39 | K46: 114.43 | L46: 12062.04 | M46: -6000.05 | N46: -8503.82 | O46: -4271.75 | P46: 0 | Q46: 140
B47: Cese Phone | C47: 46086 | D47: 6855.41 | E47: -18775.62 | F47: 35408.86 | G47: 23628.65 | H47: 830.85 | I47: 6024.56 | J47: 23232.39 | K47: 114.43 | L47: 12062.04 | M47: -6000.05 | N47: -8503.82 | O47: -4271.75 | P47: 0 | Q47: 140
... B806: Tidal | C806: 46810 | D806: 20012.51 | E806: -8148.6 | F806: 41232.86 | G806: 56456.77 | H806: 2664.77 | I806: 17347.74 | J806: 29056.39 | K806: 114.43 | L806: 12062.04 | M806: 1122.97 | N806: -4999.82 | O806: -4271.75 | P806: 0 | Q806: 3360

Sheet Notes
B1: Rent +Utilities | C1: Rent | D1: Utilities | E1: SDGE | F1: T-Mobile
A2: TOTAL | B2: 2244.11 | C2: 2195 | D2: =B2-C2 -> 49.11 | E2: 175 | F2: 54.99 | G2: =SUM(C2:F2) -> 2474.1
A3: Kulo | B3: =ROUNDUP(B$2/2-160,0) -> 963 | C3: =ROUNDUP(C$2/2-160,0) -> 938 | D3: =B3-C3 -> 25 | E3: =ROUNDUP(E$2/2,0) -> 88 | F3: =ROUNDUP(F$2/2,0) -> 28 | G3: =SUM(C3:F3) -> 1079
A4: Me | B4: =B2-B3 -> 1281.11 | C4: =C2-C3 -> 1257 | D4: =B4-C4 -> 24.11 | E4: =E2-E3 -> 87 | F4: =F2-F3 -> 26.99 | G4: =SUM(C4:F4) -> 1395.1 | H4: =1050-425 -> 625 | J4: =C4-C3 -> 319
G5: =G3+G4 -> 2474.1
B6: Limit | C6: 0.3 | D6: Balance | E6: Difference
A7: Platinum | B7: -16000 | C7: =B7*0.3 -> -4800 | D7: -6564.28 | E7: =D7-C7 -> -1764.28
A8: Go | B8: -9600 | C8: =B8*0.3 -> -2880 | D8: -9380.48 | E8: =D8-C8 -> -6500.48
A9: Line of Credit | B9: -8000 | C9: =B9*0.3 -> -2400 | D9: =Forecast!K8 -> 0 | E9: =D9-C9 -> 2400 | J9: Kulo owes for deposit on 4110
A10: Costco | B10: -8200 | C10: =B10*0.3 -> -2460 | D10: -3646 | E10: =D10-C10 -> -1186 | J10: 962
A11: CareCredit | B11: -5500 | C11: =B11*0.3 -> -1650 | D11: =Forecast!L7 -> -4271.75 | E11: =D11-C11 -> -2621.75 | J11: Kulo owes for January
B12: =SUM(B7:B11) -> -47300 | C12: =SUM(C7:C11) -> -14190 | D12: =SUM(D7:D11) -> -23862.51 | E12: =SUM(E7:E11) -> -9672.51 | J12: =1142-795 -> 347
C15: Total
A16: Plan | B16: 135
A17: Raymond phone | B17: =5+7+4.17 -> 16.17 | C17: =B17+$B$16/3 -> 61.17
A18: Internet | B18: 55 | C18: =B18 -> 55
A19: Cese phone | B19: 33.75 | C19: =B19+$B$16/3 -> 78.75
A20: Corey phone | B20: 17.92 | C20: =B20+$B$16/3 -> 62.92
C21: =SUM(C17:C20) -> 257.84
A23: Cese total | C23: 142
A24: Me total | C24: =C21-C23 -> 115.84
A27: =Forecast!J6 -> Platinum | B27: =Forecast!K6 -> Visa Go | C27: =Forecast!L6 -> Costco
A28: =Forecast!J7 -> -6311.05 | B28: =Forecast!K7 -> -8503.82 | C28: =Forecast!L7 -> -4271.75 | D28: =SUM(A28:C28) -> -19086.62
A29: 0.2499 | B29: 0.2449 | C29: 0.2674

Sheet Helper - Dashboard
A1: Transactions | B1: Dates | C1: Balance | D1: Account | F1: Transactions | G1: Dates | H1: Checking | I1: Credit | J1: Savings | K1: Net Worth | L1: ="Acct 1 - "&'Monthly budget'!F6 -> Acct 1 - US Bank | M1: ="Acct 2 - "&'Monthly budget'!G6 -> Acct 2 - Wells Fargo | N1: ="Acct 3 - "&'Monthly budget'!H6 -> Acct 3 - ADP | O1: ="Acct 4 - "&'Monthly budget'!I6 -> Acct 4 - Marcus | P1: ="Acct 5 - "&'Monthly budget'!J6 -> Acct 5 - T.Rowe Price | Q1: ="Acct 6 - "&'Monthly budget'!K6 -> Acct 6 - Platinum | R1: ="Acct 7 - "&'Monthly budget'!L6 -> Acct 7 - Visa Go | S1: ="Acct 8 - "&'Monthly budget'!M6 -> Acct 8 - CareCredit | T1: ="Acct 9 - "&'Monthly budget'!N6 -> Acct 9 - Costco | U1: ="Acct 10 - "&'Monthly budget'!O6 -> Acct 10 -
A2: {=_xlfn.VSTACK({"Transactions","Dates","Balance","Account"},_xlfn.ANCHORARRAY(W2),_xlfn.ANCHORARRAY(AA2),_xlfn.ANCHORARRAY(AE2),_xlfn.ANCHORARRAY(AI2),_xlfn.ANCHORARRAY(AM2),_xlfn.ANCHORARRAY(AQ2),_xlfn.ANCHORARRAY(AU2),_xlfn.ANCHORARRAY(AY2),_xlfn.ANCHORARRAY(BC2),_xlfn.ANCHORARRAY(BG2),_xlfn.ANCHORARRAY(BK2),_xlfn.ANCHORARRAY(BO2),_xlfn.ANCHORARRAY(BS2),_xlfn.ANCHORARRAY(BW2))} -> Transactions | B2: Dates | C2: Balance | D2: Account | F2: {=_xlfn.CHOOSECOLS(_xlfn._xlws.SORT(_xlfn._xlws.FILTER(Forecast!B:O,(Forecast!B:B=FALSE)*(Forecast!C:C<>"")),3),2)} -> Starting balance | G2: {=_xlfn.CHOOSECOLS(_xlfn._xlws.SORT(_xlfn._xlws.FILTER(Forecast!B:O,(Forecast!B:B=FALSE)*(Forecast!C:C<>"")),3),3)} -> 46081 | H2: {=_xlfn.BYROW(_xlfn.HSTACK(_xlfn.ANCHORARRAY(L2):_xlfn.ANCHORARRAY(U2)),_xlfn.LAMBDA(_xlpm.a,SUMPRODUCT(--('Monthly budget'!$F$7:$O$7="Checking"),_xlpm.a)))} -> 9843.71 | I2: {=_xlfn.BYROW(_xlfn.HSTACK(_xlfn.ANCHORARRAY(L2):_xlfn.ANCHORARRAY(U2)),_xlfn.LAMBDA(_xlpm.a,SUMPRODUCT(--('Monthly budget'!$F$7:$O$7="Credit"),_xlpm.a)))} -> -19086.62 | J2: {=_xlfn.BYROW(_xlfn.HSTACK(_xlfn.ANCHORARRAY(L2):_xlfn.ANCHORARRAY(U2)),_xlfn.LAMBDA(_xlpm.a,SUMPRODUCT(--('Monthly budget'!$F$7:$O$7="Savings"),_xlpm.a)))} -> 35408.86 | K2: {=_xlfn.BYROW(_xlfn.HSTACK(_xlfn.ANCHORARRAY(L2):_xlfn.ANCHORARRAY(U2)),_xlfn.LAMBDA(_xlpm.a,SUM(_xlpm.a)))} -> 26165.95 | L2: {=_xlfn.SCAN(0,_xlfn.CHOOSECOLS(_xlfn._xlws.SORT(_xlfn._xlws.FILTER(Forecast!B:O,(Forecast!B:B=FALSE)*(Forecast!C:C<>"")),3),4),_xlfn.LAMBDA(_xlpm.a,_xlpm.v,_xlpm.a+_xlpm.v))} -> 3775.81 | M2: {=_xlfn.SCAN(0,_xlfn.CHOOSECOLS(_xlfn._xlws.SORT(_xlfn._xlws.FILTER(Forecast!B:O,(Forecast!B:B=FALSE)*(Forecast!C:C<>"")),3),5),_xlfn.LAMBDA(_xlpm.a,_xlpm.v,_xlpm.a+_xlpm.v))} -> 6067.9 | N2: {=_xlfn.SCAN(0,_xlfn.CHOOSECOLS(_xlfn._xlws.SORT(_xlfn._xlws.FILTER(Forecast!B:O,(Forecast!B:B=FALSE)*(Forecast!C:C<>"")),3),6),_xlfn.LAMBDA(_xlpm.a,_xlpm.v,_xlpm.a+_xlpm.v))} -> 23232.39 | O2: {=_xlfn.SCAN(0,_xlfn.CHOOSECOLS(_xlfn._xlws.SORT(_xlfn._xlws.FILTER(Forecast!B:O,(Forecast!B:B=FALSE)*(Forecast!C:C<>"")),3),7),_xlfn.LAMBDA(_xlpm.a,_xlpm.v,_xlpm.a+_xlpm.v))} -> 114.43 | P2: {=_xlfn.SCAN(0,_xlfn.CHOOSECOLS(_xlfn._xlws.SORT(_xlfn._xlws.FILTER(Forecast!B:O,(Forecast!B:B=FALSE)*(Forecast!C:C<>"")),3),8),_xlfn.LAMBDA(_xlpm.a,_xlpm.v,_xlpm.a+_xlpm.v))} -> 12062.04 | Q2: {=_xlfn.SCAN(0,_xlfn.CHOOSECOLS(_xlfn._xlws.SORT(_xlfn._xlws.FILTER(Forecast!B:O,(Forecast!B:B=FALSE)*(Forecast!C:C<>"")),3),9),_xlfn.LAMBDA(_xlpm.a,_xlpm.v,_xlpm.a+_xlpm.v))} -> -6311.05 | R2: {=_xlfn.SCAN(0,_xlfn.CHOOSECOLS(_xlfn._xlws.SORT(_xlfn._xlws.FILTER(Forecast!B:O,(Forecast!B:B=FALSE)*(Forecast!C:C<>"")),3),10),_xlfn.LAMBDA(_xlpm.a,_xlpm.v,_xlpm.a+_xlpm.v))} -> -8503.82 | S2: {=_xlfn.SCAN(0,_xlfn.CHOOSECOLS(_xlfn._xlws.SORT(_xlfn._xlws.FILTER(Forecast!B:O,(Forecast!B:B=FALSE)*(Forecast!C:C<>"")),3),11),_xlfn.LAMBDA(_xlpm.a,_xlpm.v,_xlpm.a+_xlpm.v))} -> -4271.75 | T2: {=_xlfn.SCAN(0,_xlfn.CHOOSECOLS(_xlfn._xlws.SORT(_xlfn._xlws.FILTER(Forecast!B:O,(Forecast!B:B=FALSE)*(Forecast!C:C<>"")),3),12),_xlfn.LAMBDA(_xlpm.a,_xlpm.v,_xlpm.a+_xlpm.v))} -> 0 | U2: {=_xlfn.SCAN(0,_xlfn.CHOOSECOLS(_xlfn._xlws.SORT(_xlfn._xlws.FILTER(Forecast!B:O,(Forecast!B:B=FALSE)*(Forecast!C:C<>"")),3),13),_xlfn.LAMBDA(_xlpm.a,_xlpm.v,_xlpm.a+_xlpm.v))} -> 0 | W2: {=_xlfn.HSTACK(_xlfn.ANCHORARRAY($F$2):_xlfn.ANCHORARRAY($G$2),_xlfn.ANCHORARRAY(L2),IF(_xlfn.SEQUENCE(ROWS(_xlfn.ANCHORARRAY($F$2)),,1,0)=1,L1,""))} -> Starting balance | X2: 46081 | Y2: 3775.81 | Z2: Acct 1 - US Bank | AA2: {=_xlfn.HSTACK(_xlfn.ANCHORARRAY($F$2):_xlfn.ANCHORARRAY($G$2),_xlfn.ANCHORARRAY(M2),IF(_xlfn.SEQUENCE(ROWS(_xlfn.ANCHORARRAY($F$2)),,1,0)=1,M1,""))} -> Starting balance | AB2: 46081 | AC2: 6067.9 | AD2: Acct 2 - Wells Fargo | AE2: {=_xlfn.HSTACK(_xlfn.ANCHORARRAY($F$2):_xlfn.ANCHORARRAY($G$2),_xlfn.ANCHORARRAY(N2),IF(_xlfn.SEQUENCE(ROWS(_xlfn.ANCHORARRAY($F$2)),,1,0)=1,N1,""))} -> Starting balance | AF2: 46081 | AG2: 23232.39 | AH2: Acct 3 - ADP | AI2: {=_xlfn.HSTACK(_xlfn.ANCHORARRAY($F$2):_xlfn.ANCHORARRAY($G$2),_xlfn.ANCHORARRAY(O2),IF(_xlfn.SEQUENCE(ROWS(_xlfn.ANCHORARRAY($F$2)),,1,0)=1,O1,""))} -> Starting balance | AJ2: 46081 | AK2: 114.43 | AL2: Acct 4 - Marcus | AM2: {=_xlfn.HSTACK(_xlfn.ANCHORARRAY($F$2):_xlfn.ANCHORARRAY($G$2),_xlfn.ANCHORARRAY(P2),IF(_xlfn.SEQUENCE(ROWS(_xlfn.ANCHORARRAY($F$2)),,1,0)=1,P1,""))} -> Starting balance | AN2: 46081 | AO2: 12062.04 | AP2: Acct 5 - T.Rowe Price | AQ2: {=_xlfn.HSTACK(_xlfn.ANCHORARRAY($F$2):_xlfn.ANCHORARRAY($G$2),_xlfn.ANCHORARRAY(Q2),IF(_xlfn.SEQUENCE(ROWS(_xlfn.ANCHORARRAY($F$2)),,1,0)=1,Q1,""))} -> Starting balance | AR2: 46081 | AS2: -6311.05 | AT2: Acct 6 - Platinum | AU2: {=_xlfn.HSTACK(_xlfn.ANCHORARRAY($F$2):_xlfn.ANCHORARRAY($G$2),_xlfn.ANCHORARRAY(R2),IF(_xlfn.SEQUENCE(ROWS(_xlfn.ANCHORARRAY($F$2)),,1,0)=1,R1,""))} -> Starting balance | AV2: 46081 | AW2: -8503.82 | AX2: Acct 7 - Visa Go | AY2: {=_xlfn.HSTACK(_xlfn.ANCHORARRAY($F$2):_xlfn.ANCHORARRAY($G$2),_xlfn.ANCHORARRAY(S2),IF(_xlfn.SEQUENCE(ROWS(_xlfn.ANCHORARRAY($F$2)),,1,0)=1,S1,""))} -> Starting balance | AZ2: 46081 | BA2: -4271.75 | BB2: Acct 8 - CareCredit | BC2: {=_xlfn.HSTACK(_xlfn.ANCHORARRAY($F$2):_xlfn.ANCHORARRAY($G$2),_xlfn.ANCHORARRAY(T2),IF(_xlfn.SEQUENCE(ROWS(_xlfn.ANCHORARRAY($F$2)),,1,0)=1,T1,""))} -> Starting balance | BD2: 46081 | BE2: 0 | BF2: Acct 9 - Costco | BG2: {=_xlfn.HSTACK(_xlfn.ANCHORARRAY($F$2):_xlfn.ANCHORARRAY($G$2),_xlfn.ANCHORARRAY(U2),IF(_xlfn.SEQUENCE(ROWS(_xlfn.ANCHORARRAY($F$2)),,1,0)=1,U1,""))} -> Starting balance | BH2: 46081 | BI2: 0 | BJ2: Acct 10 - | BK2: {=_xlfn.HSTACK(_xlfn.ANCHORARRAY($F$2):_xlfn.ANCHORARRAY($G$2),_xlfn.ANCHORARRAY(H2),IF(_xlfn.SEQUENCE(ROWS(_xlfn.ANCHORARRAY($F$2)),,1,0)=1,H1,""))} -> Starting balance | BL2: 46081 | BM2: 9843.71 | BN2: Checking | BO2: {=_xlfn.HSTACK(_xlfn.ANCHORARRAY($F$2):_xlfn.ANCHORARRAY($G$2),_xlfn.ANCHORARRAY(I2),IF(_xlfn.SEQUENCE(ROWS(_xlfn.ANCHORARRAY($F$2)),,1,0)=1,I1,""))} -> Starting balance | BP2: 46081 | BQ2: -19086.62 | BR2: Credit | BS2: {=_xlfn.HSTACK(_xlfn.ANCHORARRAY($F$2):_xlfn.ANCHORARRAY($G$2),_xlfn.ANCHORARRAY(J2),IF(_xlfn.SEQUENCE(ROWS(_xlfn.ANCHORARRAY($F$2)),,1,0)=1,J1,""))} -> Starting balance | BT2: 46081 | BU2: 35408.86 | BV2: Savings | BW2: {=_xlfn.HSTACK(_xlfn.ANCHORARRAY($F$2):_xlfn.ANCHORARRAY($G$2),_xlfn.ANCHORARRAY(K2),IF(_xlfn.SEQUENCE(ROWS(_xlfn.ANCHORARRAY($F$2)),,1,0)=1,K1,""))} -> Starting balance | BX2: 46081 | BY2: 26165.95 | BZ2: Net Worth
A3: Starting balance | B3: 46081 | C3: 3775.81 | D3: Acct 1 - US Bank | F3: Costco Citi | G3: 46081 | H3: 9703.71 | I3: -19086.62 | J3: 35408.86 | K3: 26165.95 | L3: 3635.81 | M3: 6067.9 | N3: 23232.39 | O3: 114.43 | P3: 12062.04 | Q3: -6311.05 | R3: -8503.82 | S3: -4271.75 | T3: 0 | U3: 140 | W3: Costco Citi | X3: 46081 | Y3: 3635.81 | Z3: Acct 1 - US Bank | AA3: Costco Citi | AB3: 46081 | AC3: 6067.9 | AD3: Acct 2 - Wells Fargo | AE3: Costco Citi | AF3: 46081 | AG3: 23232.39 | AH3: Acct 3 - ADP | AI3: Costco Citi | AJ3: 46081 | AK3: 114.43 | AL3: Acct 4 - Marcus | AM3: Costco Citi | AN3: 46081 | AO3: 12062.04 | AP3: Acct 5 - T.Rowe Price | AQ3: Costco Citi | AR3: 46081 | AS3: -6311.05 | AT3: Acct 6 - Platinum | AU3: Costco Citi | AV3: 46081 | AW3: -8503.82 | AX3: Acct 7 - Visa Go | AY3: Costco Citi | AZ3: 46081 | BA3: -4271.75 | BB3: Acct 8 - CareCredit | BC3: Costco Citi | BD3: 46081 | BE3: 0 | BF3: Acct 9 - Costco | BG3: Costco Citi | BH3: 46081 | BI3: 140 | BJ3: Acct 10 - | BK3: Costco Citi | BL3: 46081 | BM3: 9703.71 | BN3: Checking | BO3: Costco Citi | BP3: 46081 | BQ3: -19086.62 | BR3: Credit | BS3: Costco Citi | BT3: 46081 | BU3: 35408.86 | BV3: Savings | BW3: Costco Citi | BX3: 46081 | BY3: 26165.95 | BZ3: Net Worth
A4: Costco Citi | B4: 46081 | C4: 3635.81 | D4: Acct 1 - US Bank | F4: Kulo SDGE | G4: 46081 | H4: 9621.71 | I4: -19086.62 | J4: 35408.86 | K4: 26083.95 | L4: 3553.81 | M4: 6067.9 | N4: 23232.39 | O4: 114.43 | P4: 12062.04 | Q4: -6311.05 | R4: -8503.82 | S4: -4271.75 | T4: 0 | U4: 140 | W4: Kulo SDGE | X4: 46081 | Y4: 3553.81 | Z4: Acct 1 - US Bank | AA4: Kulo SDGE | AB4: 46081 | AC4: 6067.9 | AD4: Acct 2 - Wells Fargo | AE4: Kulo SDGE | AF4: 46081 | AG4: 23232.39 | AH4: Acct 3 - ADP | AI4: Kulo SDGE | AJ4: 46081 | AK4: 114.43 | AL4: Acct 4 - Marcus | AM4: Kulo SDGE | AN4: 46081 | AO4: 12062.04 | AP4: Acct 5 - T.Rowe Price | AQ4: Kulo SDGE | AR4: 46081 | AS4: -6311.05 | AT4: Acct 6 - Platinum | AU4: Kulo SDGE | AV4: 46081 | AW4: -8503.82 | AX4: Acct 7 - Visa Go | AY4: Kulo SDGE | AZ4: 46081 | BA4: -4271.75 | BB4: Acct 8 - CareCredit | BC4: Kulo SDGE | BD4: 46081 | BE4: 0 | BF4: Acct 9 - Costco | BG4: Kulo SDGE | BH4: 46081 | BI4: 140 | BJ4: Acct 10 - | BK4: Kulo SDGE | BL4: 46081 | BM4: 9621.71 | BN4: Checking | BO4: Kulo SDGE | BP4: 46081 | BQ4: -19086.62 | BR4: Credit | BS4: Kulo SDGE | BT4: 46081 | BU4: 35408.86 | BV4: Savings | BW4: Kulo SDGE | BX4: 46081 | BY4: 26083.95 | BZ4: Net Worth
A5: Kulo SDGE | B5: 46081 | C5: 3553.81 | D5: Acct 1 - US Bank | F5: Groceries | G5: 46081 | H5: 9421.71 | I5: -19086.62 | J5: 35408.86 | K5: 25883.95 | L5: 3553.81 | M5: 5867.9 | N5: 23232.39 | O5: 114.43 | P5: 12062.04 | Q5: -6311.05 | R5: -8503.82 | S5: -4271.75 | T5: 0 | U5: 140 | W5: Groceries | X5: 46081 | Y5: 3553.81 | Z5: Acct 1 - US Bank | AA5: Groceries | AB5: 46081 | AC5: 5867.9 | AD5: Acct 2 - Wells Fargo | AE5: Groceries | AF5: 46081 | AG5: 23232.39 | AH5: Acct 3 - ADP | AI5: Groceries | AJ5: 46081 | AK5: 114.43 | AL5: Acct 4 - Marcus | AM5: Groceries | AN5: 46081 | AO5: 12062.04 | AP5: Acct 5 - T.Rowe Price | AQ5: Groceries | AR5: 46081 | AS5: -6311.05 | AT5: Acct 6 - Platinum | AU5: Groceries | AV5: 46081 | AW5: -8503.82 | AX5: Acct 7 - Visa Go | AY5: Groceries | AZ5: 46081 | BA5: -4271.75 | BB5: Acct 8 - CareCredit | BC5: Groceries | BD5: 46081 | BE5: 0 | BF5: Acct 9 - Costco | BG5: Groceries | BH5: 46081 | BI5: 140 | BJ5: Acct 10 - | BK5: Groceries | BL5: 46081 | BM5: 9421.71 | BN5: Checking | BO5: Groceries | BP5: 46081 | BQ5: -19086.62 | BR5: Credit | BS5: Groceries | BT5: 46081 | BU5: 35408.86 | BV5: Savings | BW5: Groceries | BX5: 46081 | BY5: 25883.95 | BZ5: Net Worth
A6: Groceries | B6: 46081 | C6: 3553.81 | D6: Acct 1 - US Bank | F6: Food & Drinks | G6: 46081 | H6: 9221.71 | I6: -19086.62 | J6: 35408.86 | K6: 25683.95 | L6: 3553.81 | M6: 5667.9 | N6: 23232.39 | O6: 114.43 | P6: 12062.04 | Q6: -6311.05 | R6: -8503.82 | S6: -4271.75 | T6: 0 | U6: 140 | W6: Food & Drinks | X6: 46081 | Y6: 3553.81 | Z6: Acct 1 - US Bank | AA6: Food & Drinks | AB6: 46081 | AC6: 5667.9 | AD6: Acct 2 - Wells Fargo | AE6: Food & Drinks | AF6: 46081 | AG6: 23232.39 | AH6: Acct 3 - ADP | AI6: Food & Drinks | AJ6: 46081 | AK6: 114.43 | AL6: Acct 4 - Marcus | AM6: Food & Drinks | AN6: 46081 | AO6: 12062.04 | AP6: Acct 5 - T.Rowe Price | AQ6: Food & Drinks | AR6: 46081 | AS6: -6311.05 | AT6: Acct 6 - Platinum | AU6: Food & Drinks | AV6: 46081 | AW6: -8503.82 | AX6: Acct 7 - Visa Go | AY6: Food & Drinks | AZ6: 46081 | BA6: -4271.75 | BB6: Acct 8 - CareCredit | BC6: Food & Drinks | BD6: 46081 | BE6: 0 | BF6: Acct 9 - Costco | BG6: Food & Drinks | BH6: 46081 | BI6: 140 | BJ6: Acct 10 - | BK6: Food & Drinks | BL6: 46081 | BM6: 9221.71 | BN6: Checking | BO6: Food & Drinks | BP6: 46081 | BQ6: -19086.62 | BR6: Credit | BS6: Food & Drinks | BT6: 46081 | BU6: 35408.86 | BV6: Savings | BW6: Food & Drinks | BX6: 46081 | BY6: 25683.95 | BZ6: Net Worth
A7: Food & Drinks | B7: 46081 | C7: 3553.81 | D7: Acct 1 - US Bank | F7: SDGE | G7: 46081 | H7: 9137.71 | I7: -19086.62 | J7: 35408.86 | K7: 25599.95 | L7: 3469.81 | M7: 5667.9 | N7: 23232.39 | O7: 114.43 | P7: 12062.04 | Q7: -6311.05 | R7: -8503.82 | S7: -4271.75 | T7: 0 | U7: 140 | W7: SDGE | X7: 46081 | Y7: 3469.81 | Z7: Acct 1 - US Bank | AA7: SDGE | AB7: 46081 | AC7: 5667.9 | AD7: Acct 2 - Wells Fargo | AE7: SDGE | AF7: 46081 | AG7: 23232.39 | AH7: Acct 3 - ADP | AI7: SDGE | AJ7: 46081 | AK7: 114.43 | AL7: Acct 4 - Marcus | AM7: SDGE | AN7: 46081 | AO7: 12062.04 | AP7: Acct 5 - T.Rowe Price | AQ7: SDGE | AR7: 46081 | AS7: -6311.05 | AT7: Acct 6 - Platinum | AU7: SDGE | AV7: 46081 | AW7: -8503.82 | AX7: Acct 7 - Visa Go | AY7: SDGE | AZ7: 46081 | BA7: -4271.75 | BB7: Acct 8 - CareCredit | BC7: SDGE | BD7: 46081 | BE7: 0 | BF7: Acct 9 - Costco | BG7: SDGE | BH7: 46081 | BI7: 140 | BJ7: Acct 10 - | BK7: SDGE | BL7: 46081 | BM7: 9137.71 | BN7: Checking | BO7: SDGE | BP7: 46081 | BQ7: -19086.62 | BR7: Credit | BS7: SDGE | BT7: 46081 | BU7: 35408.86 | BV7: Savings | BW7: SDGE | BX7: 46081 | BY7: 25599.95 | BZ7: Net Worth
A8: SDGE | B8: 46081 | C8: 3469.81 | D8: Acct 1 - US Bank | F8: Prime Ad-Free | G8: 46081 | H8: 9134.72 | I8: -19086.62 | J8: 35408.86 | K8: 25596.96 | L8: 3466.82 | M8: 5667.9 | N8: 23232.39 | O8: 114.43 | P8: 12062.04 | Q8: -6311.05 | R8: -8503.82 | S8: -4271.75 | T8: 0 | U8: 140 | W8: Prime Ad-Free | X8: 46081 | Y8: 3466.82 | Z8: Acct 1 - US Bank | AA8: Prime Ad-Free | AB8: 46081 | AC8: 5667.9 | AD8: Acct 2 - Wells Fargo | AE8: Prime Ad-Free | AF8: 46081 | AG8: 23232.39 | AH8: Acct 3 - ADP | AI8: Prime Ad-Free | AJ8: 46081 | AK8: 114.43 | AL8: Acct 4 - Marcus | AM8: Prime Ad-Free | AN8: 46081 | AO8: 12062.04 | AP8: Acct 5 - T.Rowe Price | AQ8: Prime Ad-Free | AR8: 46081 | AS8: -6311.05 | AT8: Acct 6 - Platinum | AU8: Prime Ad-Free | AV8: 46081 | AW8: -8503.82 | AX8: Acct 7 - Visa Go | AY8: Prime Ad-Free | AZ8: 46081 | BA8: -4271.75 | BB8: Acct 8 - CareCredit | BC8: Prime Ad-Free | BD8: 46081 | BE8: 0 | BF8: Acct 9 - Costco | BG8: Prime Ad-Free | BH8: 46081 | BI8: 140 | BJ8: Acct 10 - | BK8: Prime Ad-Free | BL8: 46081 | BM8: 9134.72 | BN8: Checking | BO8: Prime Ad-Free | BP8: 46081 | BQ8: -19086.62 | BR8: Credit | BS8: Prime Ad-Free | BT8: 46081 | BU8: 35408.86 | BV8: Savings | BW8: Prime Ad-Free | BX8: 46081 | BY8: 25596.96 | BZ8: Net Worth
A9: Prime Ad-Free | B9: 46081 | C9: 3466.82 | D9: Acct 1 - US Bank | F9: Disability | G9: 46082 | H9: 9491.38 | I9: -19086.62 | J9: 35408.86 | K9: 25953.62 | L9: 3466.82 | M9: 6024.56 | N9: 23232.39 | O9: 114.43 | P9: 12062.04 | Q9: -6311.05 | R9: -8503.82 | S9: -4271.75 | T9: 0 | U9: 140 | W9: Disability | X9: 46082 | Y9: 3466.82 | Z9: Acct 1 - US Bank | AA9: Disability | AB9: 46082 | AC9: 6024.56 | AD9: Acct 2 - Wells Fargo | AE9: Disability | AF9: 46082 | AG9: 23232.39 | AH9: Acct 3 - ADP | AI9: Disability | AJ9: 46082 | AK9: 114.43 | AL9: Acct 4 - Marcus | AM9: Disability | AN9: 46082 | AO9: 12062.04 | AP9: Acct 5 - T.Rowe Price | AQ9: Disability | AR9: 46082 | AS9: -6311.05 | AT9: Acct 6 - Platinum | AU9: Disability | AV9: 46082 | AW9: -8503.82 | AX9: Acct 7 - Visa Go | AY9: Disability | AZ9: 46082 | BA9: -4271.75 | BB9: Acct 8 - CareCredit | BC9: Disability | BD9: 46082 | BE9: 0 | BF9: Acct 9 - Costco | BG9: Disability | BH9: 46082 | BI9: 140 | BJ9: Acct 10 - | BK9: Disability | BL9: 46082 | BM9: 9491.38 | BN9: Checking | BO9: Disability | BP9: 46082 | BQ9: -19086.62 | BR9: Credit | BS9: Disability | BT9: 46082 | BU9: 35408.86 | BV9: Savings | BW9: Disability | BX9: 46082 | BY9: 25953.62 | BZ9: Net Worth
A10: Disability | B10: 46082 | C10: 3466.82 | D10: Acct 1 - US Bank | F10: Kulo Rent | G10: 46082 | H10: 8532.38 | I10: -19086.62 | J10: 35408.86 | K10: 24994.62 | L10: 2507.82 | M10: 6024.56 | N10: 23232.39 | O10: 114.43 | P10: 12062.04 | Q10: -6311.05 | R10: -8503.82 | S10: -4271.75 | T10: 0 | U10: 140 | W10: Kulo Rent | X10: 46082 | Y10: 2507.82 | Z10: Acct 1 - US Bank | AA10: Kulo Rent | AB10: 46082 | AC10: 6024.56 | AD10: Acct 2 - Wells Fargo | AE10: Kulo Rent | AF10: 46082 | AG10: 23232.39 | AH10: Acct 3 - ADP | AI10: Kulo Rent | AJ10: 46082 | AK10: 114.43 | AL10: Acct 4 - Marcus | AM10: Kulo Rent | AN10: 46082 | AO10: 12062.04 | AP10: Acct 5 - T.Rowe Price | AQ10: Kulo Rent | AR10: 46082 | AS10: -6311.05 | AT10: Acct 6 - Platinum | AU10: Kulo Rent | AV10: 46082 | AW10: -8503.82 | AX10: Acct 7 - Visa Go | AY10: Kulo Rent | AZ10: 46082 | BA10: -4271.75 | BB10: Acct 8 - CareCredit | BC10: Kulo Rent | BD10: 46082 | BE10: 0 | BF10: Acct 9 - Costco | BG10: Kulo Rent | BH10: 46082 | BI10: 140 | BJ10: Acct 10 - | BK10: Kulo Rent | BL10: 46082 | BM10: 8532.38 | BN10: Checking | BO10: Kulo Rent | BP10: 46082 | BQ10: -19086.62 | BR10: Credit | BS10: Kulo Rent | BT10: 46082 | BU10: 35408.86 | BV10: Savings | BW10: Kulo Rent | BX10: 46082 | BY10: 24994.62 | BZ10: Net Worth
A11: Kulo Rent | B11: 46082 | C11: 2507.82 | D11: Acct 1 - US Bank | F11: Rent | G11: 46082 | H11: 7254.41 | I11: -19086.62 | J11: 35408.86 | K11: 23716.65 | L11: 1229.85 | M11: 6024.56 | N11: 23232.39 | O11: 114.43 | P11: 12062.04 | Q11: -6311.05 | R11: -8503.82 | S11: -4271.75 | T11: 0 | U11: 140 | W11: Rent | X11: 46082 | Y11: 1229.85 | Z11: Acct 1 - US Bank | AA11: Rent | AB11: 46082 | AC11: 6024.56 | AD11: Acct 2 - Wells Fargo | AE11: Rent | AF11: 46082 | AG11: 23232.39 | AH11: Acct 3 - ADP | AI11: Rent | AJ11: 46082 | AK11: 114.43 | AL11: Acct 4 - Marcus | AM11: Rent | AN11: 46082 | AO11: 12062.04 | AP11: Acct 5 - T.Rowe Price | AQ11: Rent | AR11: 46082 | AS11: -6311.05 | AT11: Acct 6 - Platinum | AU11: Rent | AV11: 46082 | AW11: -8503.82 | AX11: Acct 7 - Visa Go | AY11: Rent | AZ11: 46082 | BA11: -4271.75 | BB11: Acct 8 - CareCredit | BC11: Rent | BD11: 46082 | BE11: 0 | BF11: Acct 9 - Costco | BG11: Rent | BH11: 46082 | BI11: 140 | BJ11: Acct 10 - | BK11: Rent | BL11: 46082 | BM11: 7254.41 | BN11: Checking | BO11: Rent | BP11: 46082 | BQ11: -19086.62 | BR11: Credit | BS11: Rent | BT11: 46082 | BU11: 35408.86 | BV11: Savings | BW11: Rent | BX11: 46082 | BY11: 23716.65 | BZ11: Net Worth
